<mujoco>
    <compiler autolimits="true" angle="radian" meshdir="assets" />
    <!-- <size memory="2G"/> -->
    <!-- <option integrator="Euler" solver="Newton" iterations="500" ls_iterations="300"/> -->
    <asset>
        <material name="grid" texrepeat="1 1" texuniform="true" rgba=".4 .4 .4 1" reflectance=".1" />
        <!-- base -->
        <mesh file="cj_003___base_1_10103_liu_mian_luo_mu__1.stl" />
        <mesh file="cj_003___base_1_10103_liu_mian_luo_mu__2.stl" />
        <mesh file="cj_003___base_1_10103_liu_mian_luo_mu__3.stl" />
        <mesh file="cj_003___base_1_10103_liu_mian_luo_mu__4.stl" />
        <mesh file="cj_003___base_1_8009_rau_5005__wai_xing_chi_cun__20240809_1.stl" />
        <mesh file="cj_003___base_1_8009_rau_5005__wai_xing_chi_cun__20240809_2.stl" />
        <mesh file="cj_003___base_1_8840_jiao_jie__1.stl" />
        <mesh file="cj_003___base_1_8840_jiao_jie__2.stl" />
        <mesh file="cj_003___base_1_8840_jiao_jie__3.stl" />
        <mesh file="cj_003___base_1_8840_jiao_jie__4.stl" />
        <mesh file="cj_003___base_1_8840_jiao_jie__5.stl" />
        <mesh file="cj_003___base_1_8840_jiao_jie__6.stl" />
        <mesh file="cj_003___base_1_8840_jiao_jie__7.stl" />
        <mesh file="cj_003___base_1_8840_jiao_jie__8.stl" />
        <mesh file="cj_003___base_1_imu_gu_ding__1.stl" />
        <mesh file="cj_003___base_1_m5_40_shuang_tong_liu_jiao_luo_zhu__1.stl" />
        <mesh file="cj_003___base_1_m5_40_shuang_tong_liu_jiao_luo_zhu__2.stl" />
        <mesh file="cj_003___base_1_m5_40_shuang_tong_liu_jiao_luo_zhu__3.stl" />
        <mesh file="cj_003___base_1_m5_40_shuang_tong_liu_jiao_luo_zhu__4.stl" />
        <mesh file="cj_003___base_1_m5_40_shuang_tong_liu_jiao_luo_zhu__5.stl" />
        <mesh file="cj_003___base_1_m5_40_shuang_tong_liu_jiao_luo_zhu__6.stl" />
        <mesh file="cj_003___base_1_m5_8_0_8_dian_pian__1.stl" />
        <mesh file="cj_003___base_1_m5_8_0_8_dian_pian__2.stl" />
        <mesh file="cj_003___base_1_m5_8_0_8_dian_pian__3.stl" />
        <mesh file="cj_003___base_1_m5_8_0_8_dian_pian__4.stl" />
        <mesh file="cj_003___base_1_m5_8_0_8_dian_pian__5.stl" />
        <mesh file="cj_003___base_1_m5_8_0_8_dian_pian__6.stl" />
        <mesh file="cj_003___base_1__ping_tou_m4_10_1.stl" />
        <mesh file="cj_003___base_1__ping_tou_m4_10_10.stl" />
        <mesh file="cj_003___base_1__ping_tou_m4_10_11.stl" />
        <mesh file="cj_003___base_1__ping_tou_m4_10_12.stl" />
        <mesh file="cj_003___base_1__ping_tou_m4_10_2.stl" />
        <mesh file="cj_003___base_1__ping_tou_m4_10_3.stl" />
        <mesh file="cj_003___base_1__ping_tou_m4_10_4.stl" />
        <mesh file="cj_003___base_1__ping_tou_m4_10_5.stl" />
        <mesh file="cj_003___base_1__ping_tou_m4_10_6.stl" />
        <mesh file="cj_003___base_1__ping_tou_m4_10_7.stl" />
        <mesh file="cj_003___base_1__ping_tou_m4_10_8.stl" />
        <mesh file="cj_003___base_1__ping_tou_m4_10_9.stl" />
        <mesh file="cj_003___base_1__ji_shen_1_1.stl" />
        <mesh file="cj_003___base_1__ji_shen_3_1.stl" />
        <mesh file="cj_003___base_1__ji_shen_3_2.stl" />
        <mesh file="cj_003___base_1__ji_shen_4_1.stl" />
        <mesh file="cj_003___base_1__bei_tou_m3_14_1.stl" />
        <mesh file="cj_003___base_1__bei_tou_m3_14_10.stl" />
        <mesh file="cj_003___base_1__bei_tou_m3_14_11.stl" />
        <mesh file="cj_003___base_1__bei_tou_m3_14_12.stl" />
        <mesh file="cj_003___base_1__bei_tou_m3_14_13.stl" />
        <mesh file="cj_003___base_1__bei_tou_m3_14_14.stl" />
        <mesh file="cj_003___base_1__bei_tou_m3_14_15.stl" />
        <mesh file="cj_003___base_1__bei_tou_m3_14_16.stl" />
        <mesh file="cj_003___base_1__bei_tou_m3_14_17.stl" />
        <mesh file="cj_003___base_1__bei_tou_m3_14_18.stl" />
        <mesh file="cj_003___base_1__bei_tou_m3_14_19.stl" />
        <mesh file="cj_003___base_1__bei_tou_m3_14_2.stl" />
        <mesh file="cj_003___base_1__bei_tou_m3_14_20.stl" />
        <mesh file="cj_003___base_1__bei_tou_m3_14_21.stl" />
        <mesh file="cj_003___base_1__bei_tou_m3_14_22.stl" />
        <mesh file="cj_003___base_1__bei_tou_m3_14_23.stl" />
        <mesh file="cj_003___base_1__bei_tou_m3_14_24.stl" />
        <mesh file="cj_003___base_1__bei_tou_m3_14_25.stl" />
        <mesh file="cj_003___base_1__bei_tou_m3_14_26.stl" />
        <mesh file="cj_003___base_1__bei_tou_m3_14_27.stl" />
        <mesh file="cj_003___base_1__bei_tou_m3_14_28.stl" />
        <mesh file="cj_003___base_1__bei_tou_m3_14_29.stl" />
        <mesh file="cj_003___base_1__bei_tou_m3_14_3.stl" />
        <mesh file="cj_003___base_1__bei_tou_m3_14_30.stl" />
        <mesh file="cj_003___base_1__bei_tou_m3_14_31.stl" />
        <mesh file="cj_003___base_1__bei_tou_m3_14_32.stl" />
        <mesh file="cj_003___base_1__bei_tou_m3_14_4.stl" />
        <mesh file="cj_003___base_1__bei_tou_m3_14_5.stl" />
        <mesh file="cj_003___base_1__bei_tou_m3_14_6.stl" />
        <mesh file="cj_003___base_1__bei_tou_m3_14_7.stl" />
        <mesh file="cj_003___base_1__bei_tou_m3_14_8.stl" />
        <mesh file="cj_003___base_1__bei_tou_m3_14_9.stl" />
        <mesh file="cj_003___base_1__bei_tou_m3_6_1.stl" />
        <mesh file="cj_003___base_1__bei_tou_m3_6_2.stl" />
        <mesh file="cj_003___base_1__bei_tou_m3_6_3.stl" />
        <mesh file="cj_003___base_1__bei_tou_m3_6_4.stl" />
        <mesh file="cj_003___base_1__bei_tou_m3_6_5.stl" />
        <mesh file="cj_003___base_1__bei_tou_m3_6_6.stl" />
        <mesh file="cj_003___base_1__bei_tou_m3_6_7.stl" />
        <mesh file="cj_003___base_1__bei_tou_m3_6_8.stl" />
        <mesh file="cj_003___base_1__bei_tou_m4_8_1.stl" />
        <mesh file="cj_003___base_1__bei_tou_m4_8_11.stl" />
        <mesh file="cj_003___base_1__bei_tou_m4_8_12.stl" />
        <mesh file="cj_003___base_1__bei_tou_m4_8_2.stl" />
        <mesh file="cj_003___base_1__bei_tou_m4_8_3.stl" />
        <mesh file="cj_003___base_1__bei_tou_m4_8_4.stl" />
        <mesh file="cj_003___base_1__bei_tou_m4_8_5.stl" />
        <mesh file="cj_003___base_1__bei_tou_m4_8_6.stl" />
        <mesh file="cj_003___base_1__bei_tou_m4_8_7.stl" />
        <mesh file="cj_003___base_1__bei_tou_m4_8_9.stl" />
        <mesh file="cj_003___base_1__bei_tou_m5_12_1.stl" />
        <mesh file="cj_003___base_1__bei_tou_m5_12_10.stl" />
        <mesh file="cj_003___base_1__bei_tou_m5_12_11.stl" />
        <mesh file="cj_003___base_1__bei_tou_m5_12_12.stl" />
        <mesh file="cj_003___base_1__bei_tou_m5_12_2.stl" />
        <mesh file="cj_003___base_1__bei_tou_m5_12_3.stl" />
        <mesh file="cj_003___base_1__bei_tou_m5_12_4.stl" />
        <mesh file="cj_003___base_1__bei_tou_m5_12_5.stl" />
        <mesh file="cj_003___base_1__bei_tou_m5_12_6.stl" />
        <mesh file="cj_003___base_1__bei_tou_m5_12_7.stl" />
        <mesh file="cj_003___base_1__bei_tou_m5_12_8.stl" />
        <mesh file="cj_003___base_1__bei_tou_m5_12_9.stl" />

        <!-- left_hip -->
        <mesh file="cj_003___left_hip_1_6621_jiao_jie__1.stl" />
        <mesh file="cj_003___left_hip_1_6621_jiao_jie__2.stl" />
        <mesh file="cj_003___left_hip_1_6621_jiao_jie__3.stl" />
        <mesh file="cj_003___left_hip_1_6621_jiao_jie__4.stl" />
        <mesh file="cj_003___left_hip_1_6621_jiao_jie__5.stl" />
        <mesh file="cj_003___left_hip_1_6621_jiao_jie__6.stl" />
        <mesh file="cj_003___left_hip_1_8009_rau_5005__wai_xing_chi_cun__20240809_1.stl" />
        <mesh file="cj_003___left_hip_1__da_tui_dian_ji_gu_ding_1_1.stl" />
        <mesh file="cj_003___left_hip_1__da_tui_dian_ji_gu_ding_2_1.stl" />
        <mesh file="cj_003___left_hip_1__da_tui_dian_ji_gu_ding_3_1.stl" />
        <mesh file="cj_003___left_hip_1__da_tui_dian_ji_gu_ding_4_1.stl" />
        <mesh file="cj_003___left_hip_1__da_tui_dian_ji_gu_ding_4_2.stl" />
        <mesh file="cj_003___left_hip_1__da_tui_dian_ji_gu_ding_5_1.stl" />
        <mesh file="cj_003___left_hip_1__ping_tou_m3_10_12.stl" />
        <mesh file="cj_003___left_hip_1__ping_tou_m3_10_13.stl" />
        <mesh file="cj_003___left_hip_1__ping_tou_m3_10_15.stl" />
        <mesh file="cj_003___left_hip_1__ping_tou_m3_10_16.stl" />
        <mesh file="cj_003___left_hip_1__ping_tou_m3_10_2.stl" />
        <mesh file="cj_003___left_hip_1__ping_tou_m3_10_3.stl" />
        <mesh file="cj_003___left_hip_1__ping_tou_m3_10_7.stl" />
        <mesh file="cj_003___left_hip_1__ping_tou_m3_10_8.stl" />
        <mesh file="cj_003___left_hip_1__ping_tou_m3_10_9.stl" />
        <mesh file="cj_003___left_hip_1__ping_tou_m3_16_1.stl" />
        <mesh file="cj_003___left_hip_1__ping_tou_m3_16_2.stl" />
        <mesh file="cj_003___left_hip_1__ping_tou_m3_16_3.stl" />
        <mesh file="cj_003___left_hip_1__ping_tou_m3_16_4.stl" />
        <mesh file="cj_003___left_hip_1__ping_tou_m4_10_1.stl" />
        <mesh file="cj_003___left_hip_1__ping_tou_m4_10_3.stl" />
        <mesh file="cj_003___left_hip_1__ping_tou_m4_10_4.stl" />
        <mesh file="cj_003___left_hip_1__ping_tou_m4_10_5.stl" />
        <mesh file="cj_003___left_hip_1__ping_tou_m4_10_6.stl" />
        <mesh file="cj_003___left_hip_1__ping_tou_m5_14_1.stl" />
        <mesh file="cj_003___left_hip_1__ping_tou_m5_14_2.stl" />
        <mesh file="cj_003___left_hip_1__ping_tou_m5_14_3.stl" />
        <mesh file="cj_003___left_hip_1__ping_tou_m5_14_4.stl" />
        <mesh file="cj_003___left_hip_1__ping_tou_m5_14_5.stl" />
        <mesh file="cj_003___left_hip_1__ping_tou_m5_14_6.stl" />
        <mesh file="cj_003___left_hip_1__bei_tou_m3_12_1.stl" />
        <mesh file="cj_003___left_hip_1__bei_tou_m3_12_2.stl" />
        <mesh file="cj_003___left_hip_1__bei_tou_m3_12_3.stl" />
        <mesh file="cj_003___left_hip_1__bei_tou_m3_12_4.stl" />
        <mesh file="cj_003___left_hip_1__bei_tou_m3_12_5.stl" />
        <mesh file="cj_003___left_hip_1__bei_tou_m3_12_6.stl" />
        <mesh file="cj_003___left_hip_1__bei_tou_m3_12_7.stl" />
        <mesh file="cj_003___left_hip_1__bei_tou_m3_12_8.stl" />
        <mesh file="cj_003___left_hip_1__bei_tou_m4_8_1.stl" />
        <mesh file="cj_003___left_hip_1__bei_tou_m4_8_2.stl" />
        <mesh file="cj_003___left_hip_1__bei_tou_m4_8_3.stl" />
        <mesh file="cj_003___left_hip_1__bei_tou_m4_8_4.stl" />
        <mesh file="cj_003___left_hip_1__bei_tou_m4_8_5.stl" />
        <mesh file="cj_003___left_hip_1__bei_tou_m4_8_6.stl" />

        <!-- left_thigh -->
        <mesh file="cj_003___left_thigh_2_8009_rau_5005__wai_xing_chi_cun__20240809_1.stl" />
        <mesh file="cj_003___left_thigh_2_m5_40_shuang_tong_liu_jiao_luo_zhu__1.stl" />
        <mesh file="cj_003___left_thigh_2_m5_40_shuang_tong_liu_jiao_luo_zhu__2.stl" />
        <mesh file="cj_003___left_thigh_2_m5_40_shuang_tong_liu_jiao_luo_zhu__3.stl" />
        <mesh file="cj_003___left_thigh_2_m5_8_0_8_dian_pian__1.stl" />
        <mesh file="cj_003___left_thigh_2_m5_8_0_8_dian_pian__2.stl" />
        <mesh file="cj_003___left_thigh_2_m5_8_0_8_dian_pian__3.stl" />
        <mesh file="cj_003___left_thigh_2__wai_liu_jiao_m4_22_1.stl" />
        <mesh file="cj_003___left_thigh_2__wai_liu_jiao_m4_22_2.stl" />
        <mesh file="cj_003___left_thigh_2__wai_liu_jiao_m4_22_3.stl" />
        <mesh file="cj_003___left_thigh_2__wai_liu_jiao_m4_22_4.stl" />
        <mesh file="cj_003___left_thigh_2__wai_liu_jiao_m4_22_5.stl" />
        <mesh file="cj_003___left_thigh_2__da_tui_dian_ji_gu_ding_5_1.stl" />
        <mesh file="cj_003___left_thigh_2__da_tui_dian_ji_gu_ding_dian_kuai__1.stl" />
        <mesh file="cj_003___left_thigh_2__da_tui_dian_ji_gu_ding_dian_kuai__2.stl" />
        <mesh file="cj_003___left_thigh_2__da_tui_di_yi_ceng__1.stl" />
        <mesh file="cj_003___left_thigh_2__da_tui_di_er_ceng__1.stl" />
        <mesh file="cj_003___left_thigh_2__da_tui_xi_guan_jie_dian_kuai__1.stl" />
        <mesh file="cj_003___left_thigh_2__da_tui_xi_guan_jie_dian_kuai__2.stl" />
        <mesh file="cj_003___left_thigh_2__xiao_tui_dian_ji_lian_jie___lv_he_jin__1.stl" />
        <mesh file="cj_003___left_thigh_2__ping_tou_m5_22_1.stl" />
        <mesh file="cj_003___left_thigh_2__ping_tou_m5_22_2.stl" />
        <mesh file="cj_003___left_thigh_2__ping_tou_m5_22_3.stl" />
        <mesh file="cj_003___left_thigh_2__ping_tou_m5_22_4.stl" />
        <mesh file="cj_003___left_thigh_2__ping_tou_m5_22_5.stl" />
        <mesh file="cj_003___left_thigh_2__ping_tou_m5_22_6.stl" />
        <mesh file="cj_003___left_thigh_2__bei_tou_m3_55_1.stl" />
        <mesh file="cj_003___left_thigh_2__bei_tou_m3_55_2.stl" />
        <mesh file="cj_003___left_thigh_2__bei_tou_m3_55_3.stl" />
        <mesh file="cj_003___left_thigh_2__bei_tou_m3_55_4.stl" />
        <mesh file="cj_003___left_thigh_2__bei_tou_m3_55_5.stl" />
        <mesh file="cj_003___left_thigh_2__bei_tou_m3_55_6.stl" />
        <mesh file="cj_003___left_thigh_2__bei_tou_m4_10_1.stl" />
        <mesh file="cj_003___left_thigh_2__bei_tou_m4_10_2.stl" />
        <mesh file="cj_003___left_thigh_2__bei_tou_m4_10_3.stl" />
        <mesh file="cj_003___left_thigh_2__bei_tou_m4_10_4.stl" />
        <mesh file="cj_003___left_thigh_2__bei_tou_m4_10_5.stl" />
        <mesh file="cj_003___left_thigh_2__bei_tou_m4_10_6.stl" />
        <mesh file="cj_003___left_thigh_2__bei_tou_m5_12_1.stl" />
        <mesh file="cj_003___left_thigh_2__bei_tou_m5_12_2.stl" />
        <mesh file="cj_003___left_thigh_2__bei_tou_m5_12_3.stl" />
        <mesh file="cj_003___left_thigh_2__bei_tou_m5_12_4.stl" />
        <mesh file="cj_003___left_thigh_2__bei_tou_m5_12_5.stl" />
        <mesh file="cj_003___left_thigh_2__bei_tou_m5_12_6.stl" />
        <mesh file="cj_003___left_thigh_2__xi_guan_jie_zhou_cheng__1.stl" />

        <!-- left_calf -->
        <mesh file="cj_003___left_calf_1_m3_fang_hua_luo_mu__1.stl" />
        <mesh file="cj_003___left_calf_1_m3_fang_hua_luo_mu__2.stl" />
        <mesh file="cj_003___left_calf_1_m3_fang_hua_luo_mu__3.stl" />
        <mesh file="cj_003___left_calf_1_m3_fang_hua_luo_mu__4.stl" />
        <mesh file="cj_003___left_calf_1_m3_fang_hua_luo_mu__5.stl" />
        <mesh file="cj_003___left_calf_1_m3_fang_hua_luo_mu__6.stl" />
        <mesh file="cj_003___left_calf_1_m4_12_shuang_tong_liu_jiao_luo_zhu__1.stl" />
        <mesh file="cj_003___left_calf_1_m4_12_shuang_tong_liu_jiao_luo_zhu__2.stl" />
        <mesh file="cj_003___left_calf_1_m4_fang_hua_luo_mu__1.stl" />
        <mesh file="cj_003___left_calf_1_m4_fang_hua_luo_mu__2.stl" />
        <mesh file="cj_003___left_calf_1_m4_fang_hua_luo_mu__3.stl" />
        <mesh file="cj_003___left_calf_1_m4_fang_hua_luo_mu__4.stl" />
        <mesh file="cj_003___left_calf_1_m4_fang_hua_luo_mu__5.stl" />
        <mesh file="cj_003___left_calf_1_m4_fang_hua_luo_mu__6.stl" />
        <mesh file="cj_003___left_calf_1_m4_fang_hua_luo_mu__7.stl" />
        <mesh file="cj_003___left_calf_1_m4_fang_hua_luo_mu__8.stl" />
        <mesh file="cj_003___left_calf_1_m5_fang_hua_luo_mu__1.stl" />
        <mesh file="cj_003___left_calf_1__sai_da_luo_si_m6_50_5_1.stl" />
        <mesh file="cj_003___left_calf_1__xiao_tui__1.stl" />
        <mesh file="cj_003___left_calf_1__xiao_tui__2.stl" />
        <mesh file="cj_003___left_calf_1__ping_tou_m4_30_1.stl" />
        <mesh file="cj_003___left_calf_1__ping_tou_m4_30_2.stl" />
        <mesh file="cj_003___left_calf_1__ping_tou_m4_30_3.stl" />
        <mesh file="cj_003___left_calf_1__ping_tou_m4_30_4.stl" />
        <mesh file="cj_003___left_calf_1__ping_tou_m4_30_5.stl" />
        <mesh file="cj_003___left_calf_1__ping_tou_m4_30_6.stl" />
        <mesh file="cj_003___left_calf_1__ping_tou_m4_30_7.stl" />
        <mesh file="cj_003___left_calf_1__ping_tou_m4_30_8.stl" />
        <mesh file="cj_003___left_calf_1__bei_tou_m3_10_1.stl" />
        <mesh file="cj_003___left_calf_1__bei_tou_m3_10_2.stl" />
        <mesh file="cj_003___left_calf_1__bei_tou_m3_10_3.stl" />
        <mesh file="cj_003___left_calf_1__bei_tou_m3_10_4.stl" />
        <mesh file="cj_003___left_calf_1__bei_tou_m3_25_1.stl" />
        <mesh file="cj_003___left_calf_1__bei_tou_m3_25_2.stl" />
        <mesh file="cj_003___left_calf_1__bei_tou_m3_25_3.stl" />
        <mesh file="cj_003___left_calf_1__bei_tou_m3_25_4.stl" />
        <mesh file="cj_003___left_calf_1__bei_tou_m3_25_5.stl" />
        <mesh file="cj_003___left_calf_1__bei_tou_m3_25_6.stl" />
        <mesh file="cj_003___left_calf_1__xi_guan_jie_xiao_tui_zhi_cheng_zhu__1.stl" />
        <mesh file="cj_003___left_calf_1__xi_guan_jie_lian_gan_dian_zhu__1.stl" />

        <!-- left_point_foot2 -->
        <mesh file="cj_003___left_point_foot2_1__lun_zu_mo_duan__1.stl" />
        <mesh file="cj_003___left_point_foot2_1__lun_zu_mo_duan__2.stl" />
        <mesh file="cj_003___left_point_foot2_1__lun_zu_mo_duan___shen_gou_qiu_gu_ding__1.stl" />

        <!-- left_connect1 -->

        <mesh file="cj_003___left_connect1_1_8009_lian_gan__1.stl" />
        <mesh file="cj_003___left_connect1_1_m5_fang_hua_luo_mu__1.stl" />
        <mesh file="cj_003___left_connect1_1__sai_da_luo_si_m6_12_5_1.stl" />
        <mesh file="cj_003___left_connect1_1__ping_tou_m5_12_1.stl" />
        <mesh file="cj_003___left_connect1_1__ping_tou_m5_12_2.stl" />
        <mesh file="cj_003___left_connect1_1__ping_tou_m5_12_3.stl" />
        <mesh file="cj_003___left_connect1_1__ping_tou_m5_12_4.stl" />
        <mesh file="cj_003___left_connect1_1__ping_tou_m5_12_5.stl" />
        <mesh file="cj_003___left_connect1_1__ping_tou_m5_12_6.stl" />

        <!-- left_connect2 -->
        <mesh file="cj_003___left_connect2_1_m6_10_1_dian_pian__1.stl" />
        <mesh file="cj_003___left_connect2_1_m6_10_1_dian_pian__2.stl" />
        <mesh file="cj_003___left_connect2_1_m6_18_2_dian_pian__1.stl" />
        <mesh file="cj_003___left_connect2_1_m6_18_2_dian_pian__2.stl" />
        <mesh file="cj_003___left_connect2_1__xiao_fa_lan_zhou_cheng__1.stl" />
        <mesh file="cj_003___left_connect2_1__xiao_fa_lan_zhou_cheng__2.stl" />
        <mesh file="cj_003___left_connect2_1__lian_gan__1.stl" />

        <!-- left_wheel_foot -->
        <mesh file="cj_003___left_wheel_foot_1_220_lun_gu__1.stl" />
        <mesh file="cj_003___left_wheel_foot_1__xiao_mi_shen_gou_qiu_gu_ding__1.stl" />
        <mesh file="cj_003___left_wheel_foot_1__xiao_mi_dian_ji__1.stl" />
        <mesh file="cj_003___left_wheel_foot_1__xiao_mi_dian_ji_shen_gou_qiu_zhou_cheng__1.stl" />
        <mesh file="cj_003___left_wheel_foot_1__xiao_mi_dian_ji_shu_chu_dian_kuai___ya_ban__1.stl" />
        <mesh
            file="cj_003___left_wheel_foot_1__xiao_mi_dian_ji_shu_chu_dian_kuai___dian_pian__1.stl" />
        <mesh file="cj_003___left_wheel_foot_1__xiao_mi_dian_ji_shu_chu_dian_kuai___da_yin__1.stl" />
        <mesh file="cj_003___left_wheel_foot_1__ping_tou_m3_25_1.stl" />
        <mesh file="cj_003___left_wheel_foot_1__ping_tou_m3_25_2.stl" />
        <mesh file="cj_003___left_wheel_foot_1__ping_tou_m3_25_3.stl" />
        <mesh file="cj_003___left_wheel_foot_1__ping_tou_m3_25_4.stl" />
        <mesh file="cj_003___left_wheel_foot_1__ping_tou_m3_25_5.stl" />
        <mesh file="cj_003___left_wheel_foot_1__ping_tou_m3_25_6.stl" />
        <mesh file="cj_003___left_wheel_foot_1__ping_tou_m3_25_7.stl" />
        <mesh file="cj_003___left_wheel_foot_1__ping_tou_m3_25_8.stl" />
        <mesh file="cj_003___left_wheel_foot_1__ping_tou_m3_25_9.stl" />
        <mesh file="cj_003___left_wheel_foot_1__bei_tou_m4_35_1.stl" />
        <mesh file="cj_003___left_wheel_foot_1__bei_tou_m4_35_2.stl" />
        <mesh file="cj_003___left_wheel_foot_1__bei_tou_m4_35_3.stl" />
        <mesh file="cj_003___left_wheel_foot_1__bei_tou_m4_35_4.stl" />
        <mesh file="cj_003___left_wheel_foot_1__bei_tou_m4_35_5.stl" />
        <mesh file="cj_003___left_wheel_foot_1__bei_tou_m4_35_6.stl" />
        <mesh file="cj_003___left_wheel_foot_1__xiang_jiao_bao_lun__1.stl" />
        <mesh file="cj_003___left_wheel_foot_1__lun_ping_mian_gun_zhen_zhou_cheng__1.stl" />


        <!-- right_hip -->
        <mesh file="cj_003___right_hip_1_6621_jiao_jie__1.stl" />
        <mesh file="cj_003___right_hip_1_6621_jiao_jie__2.stl" />
        <mesh file="cj_003___right_hip_1_6621_jiao_jie__3.stl" />
        <mesh file="cj_003___right_hip_1_6621_jiao_jie__4.stl" />
        <mesh file="cj_003___right_hip_1_6621_jiao_jie__5.stl" />
        <mesh file="cj_003___right_hip_1_6621_jiao_jie__6.stl" />
        <mesh file="cj_003___right_hip_1_8009_rau_5005__wai_xing_chi_cun__20240809_1.stl" />
        <mesh file="cj_003___right_hip_1__da_tui_dian_ji_gu_ding_1_1.stl" />
        <mesh file="cj_003___right_hip_1__da_tui_dian_ji_gu_ding_2_1.stl" />
        <mesh file="cj_003___right_hip_1__da_tui_dian_ji_gu_ding_3_1.stl" />
        <mesh file="cj_003___right_hip_1__da_tui_dian_ji_gu_ding_4_1.stl" />
        <mesh file="cj_003___right_hip_1__da_tui_dian_ji_gu_ding_4_2.stl" />
        <mesh file="cj_003___right_hip_1__da_tui_dian_ji_gu_ding_5_1.stl" />
        <mesh file="cj_003___right_hip_1__ping_tou_m3_10_12.stl" />
        <mesh file="cj_003___right_hip_1__ping_tou_m3_10_13.stl" />
        <mesh file="cj_003___right_hip_1__ping_tou_m3_10_15.stl" />
        <mesh file="cj_003___right_hip_1__ping_tou_m3_10_16.stl" />
        <mesh file="cj_003___right_hip_1__ping_tou_m3_10_2.stl" />
        <mesh file="cj_003___right_hip_1__ping_tou_m3_10_3.stl" />
        <mesh file="cj_003___right_hip_1__ping_tou_m3_10_7.stl" />
        <mesh file="cj_003___right_hip_1__ping_tou_m3_10_8.stl" />
        <mesh file="cj_003___right_hip_1__ping_tou_m3_10_9.stl" />
        <mesh file="cj_003___right_hip_1__ping_tou_m3_16_1.stl" />
        <mesh file="cj_003___right_hip_1__ping_tou_m3_16_2.stl" />
        <mesh file="cj_003___right_hip_1__ping_tou_m3_16_3.stl" />
        <mesh file="cj_003___right_hip_1__ping_tou_m3_16_4.stl" />
        <mesh file="cj_003___right_hip_1__ping_tou_m4_10_1.stl" />
        <mesh file="cj_003___right_hip_1__ping_tou_m4_10_3.stl" />
        <mesh file="cj_003___right_hip_1__ping_tou_m4_10_4.stl" />
        <mesh file="cj_003___right_hip_1__ping_tou_m4_10_5.stl" />
        <mesh file="cj_003___right_hip_1__ping_tou_m4_10_6.stl" />
        <mesh file="cj_003___right_hip_1__ping_tou_m5_14_1.stl" />
        <mesh file="cj_003___right_hip_1__ping_tou_m5_14_2.stl" />
        <mesh file="cj_003___right_hip_1__ping_tou_m5_14_3.stl" />
        <mesh file="cj_003___right_hip_1__ping_tou_m5_14_4.stl" />
        <mesh file="cj_003___right_hip_1__ping_tou_m5_14_5.stl" />
        <mesh file="cj_003___right_hip_1__ping_tou_m5_14_6.stl" />
        <mesh file="cj_003___right_hip_1__bei_tou_m3_12_1.stl" />
        <mesh file="cj_003___right_hip_1__bei_tou_m3_12_2.stl" />
        <mesh file="cj_003___right_hip_1__bei_tou_m3_12_3.stl" />
        <mesh file="cj_003___right_hip_1__bei_tou_m3_12_4.stl" />
        <mesh file="cj_003___right_hip_1__bei_tou_m3_12_5.stl" />
        <mesh file="cj_003___right_hip_1__bei_tou_m3_12_6.stl" />
        <mesh file="cj_003___right_hip_1__bei_tou_m3_12_7.stl" />
        <mesh file="cj_003___right_hip_1__bei_tou_m3_12_8.stl" />
        <mesh file="cj_003___right_hip_1__bei_tou_m4_8_1.stl" />
        <mesh file="cj_003___right_hip_1__bei_tou_m4_8_2.stl" />
        <mesh file="cj_003___right_hip_1__bei_tou_m4_8_3.stl" />
        <mesh file="cj_003___right_hip_1__bei_tou_m4_8_4.stl" />
        <mesh file="cj_003___right_hip_1__bei_tou_m4_8_5.stl" />
        <mesh file="cj_003___right_hip_1__bei_tou_m4_8_6.stl" />


        <!-- right_thigh -->

        <mesh file="cj_003___right_thigh_1_8009_rau_5005__wai_xing_chi_cun__20240809_1.stl" />
        <mesh file="cj_003___right_thigh_1_m5_40_shuang_tong_liu_jiao_luo_zhu__1.stl" />
        <mesh file="cj_003___right_thigh_1_m5_40_shuang_tong_liu_jiao_luo_zhu__2.stl" />
        <mesh file="cj_003___right_thigh_1_m5_40_shuang_tong_liu_jiao_luo_zhu__3.stl" />
        <mesh file="cj_003___right_thigh_1_m5_8_0_8_dian_pian__1.stl" />
        <mesh file="cj_003___right_thigh_1_m5_8_0_8_dian_pian__2.stl" />
        <mesh file="cj_003___right_thigh_1_m5_8_0_8_dian_pian__3.stl" />
        <mesh file="cj_003___right_thigh_1__wai_liu_jiao_m4_22_1.stl" />
        <mesh file="cj_003___right_thigh_1__wai_liu_jiao_m4_22_2.stl" />
        <mesh file="cj_003___right_thigh_1__wai_liu_jiao_m4_22_3.stl" />
        <mesh file="cj_003___right_thigh_1__wai_liu_jiao_m4_22_4.stl" />
        <mesh file="cj_003___right_thigh_1__wai_liu_jiao_m4_22_5.stl" />
        <mesh file="cj_003___right_thigh_1__da_tui_dian_ji_gu_ding_5_1.stl" />
        <mesh file="cj_003___right_thigh_1__da_tui_dian_ji_gu_ding_dian_kuai__1.stl" />
        <mesh file="cj_003___right_thigh_1__da_tui_dian_ji_gu_ding_dian_kuai__2.stl" />
        <mesh file="cj_003___right_thigh_1__da_tui_di_yi_ceng__1.stl" />
        <mesh file="cj_003___right_thigh_1__da_tui_di_er_ceng__1.stl" />
        <mesh file="cj_003___right_thigh_1__da_tui_xi_guan_jie_dian_kuai__1.stl" />
        <mesh file="cj_003___right_thigh_1__da_tui_xi_guan_jie_dian_kuai__2.stl" />
        <mesh file="cj_003___right_thigh_1__xiao_tui_dian_ji_lian_jie___lv_he_jin__1.stl" />
        <mesh file="cj_003___right_thigh_1__ping_tou_m5_22_1.stl" />
        <mesh file="cj_003___right_thigh_1__ping_tou_m5_22_2.stl" />
        <mesh file="cj_003___right_thigh_1__ping_tou_m5_22_3.stl" />
        <mesh file="cj_003___right_thigh_1__ping_tou_m5_22_4.stl" />
        <mesh file="cj_003___right_thigh_1__ping_tou_m5_22_5.stl" />
        <mesh file="cj_003___right_thigh_1__ping_tou_m5_22_6.stl" />
        <mesh file="cj_003___right_thigh_1__bei_tou_m3_55_1.stl" />
        <mesh file="cj_003___right_thigh_1__bei_tou_m3_55_2.stl" />
        <mesh file="cj_003___right_thigh_1__bei_tou_m3_55_3.stl" />
        <mesh file="cj_003___right_thigh_1__bei_tou_m3_55_4.stl" />
        <mesh file="cj_003___right_thigh_1__bei_tou_m3_55_5.stl" />
        <mesh file="cj_003___right_thigh_1__bei_tou_m3_55_6.stl" />
        <mesh file="cj_003___right_thigh_1__bei_tou_m4_10_1.stl" />
        <mesh file="cj_003___right_thigh_1__bei_tou_m4_10_2.stl" />
        <mesh file="cj_003___right_thigh_1__bei_tou_m4_10_3.stl" />
        <mesh file="cj_003___right_thigh_1__bei_tou_m4_10_4.stl" />
        <mesh file="cj_003___right_thigh_1__bei_tou_m4_10_5.stl" />
        <mesh file="cj_003___right_thigh_1__bei_tou_m4_10_6.stl" />
        <mesh file="cj_003___right_thigh_1__bei_tou_m5_12_1.stl" />
        <mesh file="cj_003___right_thigh_1__bei_tou_m5_12_2.stl" />
        <mesh file="cj_003___right_thigh_1__bei_tou_m5_12_3.stl" />
        <mesh file="cj_003___right_thigh_1__bei_tou_m5_12_4.stl" />
        <mesh file="cj_003___right_thigh_1__bei_tou_m5_12_5.stl" />
        <mesh file="cj_003___right_thigh_1__bei_tou_m5_12_6.stl" />
        <mesh file="cj_003___right_thigh_1__xi_guan_jie_zhou_cheng__1.stl" />

        <!-- right_calf -->
        <mesh file="cj_003___right_calf_1_m3_fang_hua_luo_mu__1.stl" />
        <mesh file="cj_003___right_calf_1_m3_fang_hua_luo_mu__2.stl" />
        <mesh file="cj_003___right_calf_1_m3_fang_hua_luo_mu__3.stl" />
        <mesh file="cj_003___right_calf_1_m3_fang_hua_luo_mu__4.stl" />
        <mesh file="cj_003___right_calf_1_m3_fang_hua_luo_mu__5.stl" />
        <mesh file="cj_003___right_calf_1_m3_fang_hua_luo_mu__6.stl" />
        <mesh file="cj_003___right_calf_1_m4_12_shuang_tong_liu_jiao_luo_zhu__1.stl" />
        <mesh file="cj_003___right_calf_1_m4_12_shuang_tong_liu_jiao_luo_zhu__2.stl" />
        <mesh file="cj_003___right_calf_1_m4_fang_hua_luo_mu__1.stl" />
        <mesh file="cj_003___right_calf_1_m4_fang_hua_luo_mu__2.stl" />
        <mesh file="cj_003___right_calf_1_m4_fang_hua_luo_mu__3.stl" />
        <mesh file="cj_003___right_calf_1_m4_fang_hua_luo_mu__4.stl" />
        <mesh file="cj_003___right_calf_1_m4_fang_hua_luo_mu__5.stl" />
        <mesh file="cj_003___right_calf_1_m4_fang_hua_luo_mu__6.stl" />
        <mesh file="cj_003___right_calf_1_m4_fang_hua_luo_mu__7.stl" />
        <mesh file="cj_003___right_calf_1_m4_fang_hua_luo_mu__8.stl" />
        <mesh file="cj_003___right_calf_1_m5_fang_hua_luo_mu__1.stl" />
        <mesh file="cj_003___right_calf_1__sai_da_luo_si_m6_50_5_1.stl" />
        <mesh file="cj_003___right_calf_1__xiao_tui__1.stl" />
        <mesh file="cj_003___right_calf_1__xiao_tui__2.stl" />
        <mesh file="cj_003___right_calf_1__ping_tou_m4_30_1.stl" />
        <mesh file="cj_003___right_calf_1__ping_tou_m4_30_2.stl" />
        <mesh file="cj_003___right_calf_1__ping_tou_m4_30_3.stl" />
        <mesh file="cj_003___right_calf_1__ping_tou_m4_30_4.stl" />
        <mesh file="cj_003___right_calf_1__ping_tou_m4_30_5.stl" />
        <mesh file="cj_003___right_calf_1__ping_tou_m4_30_6.stl" />
        <mesh file="cj_003___right_calf_1__ping_tou_m4_30_7.stl" />
        <mesh file="cj_003___right_calf_1__ping_tou_m4_30_8.stl" />
        <mesh file="cj_003___right_calf_1__bei_tou_m3_10_1.stl" />
        <mesh file="cj_003___right_calf_1__bei_tou_m3_10_2.stl" />
        <mesh file="cj_003___right_calf_1__bei_tou_m3_10_3.stl" />
        <mesh file="cj_003___right_calf_1__bei_tou_m3_10_4.stl" />
        <mesh file="cj_003___right_calf_1__bei_tou_m3_25_1.stl" />
        <mesh file="cj_003___right_calf_1__bei_tou_m3_25_2.stl" />
        <mesh file="cj_003___right_calf_1__bei_tou_m3_25_3.stl" />
        <mesh file="cj_003___right_calf_1__bei_tou_m3_25_4.stl" />
        <mesh file="cj_003___right_calf_1__bei_tou_m3_25_5.stl" />
        <mesh file="cj_003___right_calf_1__bei_tou_m3_25_6.stl" />
        <mesh file="cj_003___right_calf_1__xi_guan_jie_xiao_tui_zhi_cheng_zhu__1.stl" />
        <mesh file="cj_003___right_calf_1__xi_guan_jie_lian_gan_dian_zhu__1.stl" />

        <!-- right_point_foot2 -->
        <mesh file="cj_003___right_point_foot2_1__lun_zu_mo_duan__1.stl" />
        <mesh file="cj_003___right_point_foot2_1__lun_zu_mo_duan__2.stl" />
        <mesh file="cj_003___right_point_foot2_1__lun_zu_mo_duan___shen_gou_qiu_gu_ding__1.stl" />

        <!-- right_connect1 -->
        <mesh file="cj_003___right_connect1_1_8009_lian_gan__1.stl" />
        <mesh file="cj_003___right_connect1_1_m5_fang_hua_luo_mu__1.stl" />
        <mesh file="cj_003___right_connect1_1__sai_da_luo_si_m6_12_5_1.stl" />
        <mesh file="cj_003___right_connect1_1__ping_tou_m5_12_1.stl" />
        <mesh file="cj_003___right_connect1_1__ping_tou_m5_12_2.stl" />
        <mesh file="cj_003___right_connect1_1__ping_tou_m5_12_3.stl" />
        <mesh file="cj_003___right_connect1_1__ping_tou_m5_12_4.stl" />
        <mesh file="cj_003___right_connect1_1__ping_tou_m5_12_5.stl" />
        <mesh file="cj_003___right_connect1_1__ping_tou_m5_12_6.stl" />

        <!-- right_connect2 -->
        <mesh file="cj_003___right_connect2_1_m6_10_1_dian_pian__1.stl" />
        <mesh file="cj_003___right_connect2_1_m6_10_1_dian_pian__2.stl" />
        <mesh file="cj_003___right_connect2_1_m6_18_2_dian_pian__1.stl" />
        <mesh file="cj_003___right_connect2_1_m6_18_2_dian_pian__2.stl" />
        <mesh file="cj_003___right_connect2_1__xiao_fa_lan_zhou_cheng__1.stl" />
        <mesh file="cj_003___right_connect2_1__xiao_fa_lan_zhou_cheng__2.stl" />
        <mesh file="cj_003___right_connect2_1__lian_gan__1.stl" />

        <!-- right_wheel_foot -->
        <mesh file="cj_003___right_wheel_foot_1_220_lun_gu__1.stl" />
        <mesh file="cj_003___right_wheel_foot_1__xiao_mi_shen_gou_qiu_gu_ding__1.stl" />
        <mesh file="cj_003___right_wheel_foot_1__xiao_mi_dian_ji__1.stl" />
        <mesh file="cj_003___right_wheel_foot_1__xiao_mi_dian_ji_shen_gou_qiu_zhou_cheng__1.stl" />
        <mesh file="cj_003___right_wheel_foot_1__xiao_mi_dian_ji_shu_chu_dian_kuai___ya_ban__1.stl" />
        <mesh
            file="cj_003___right_wheel_foot_1__xiao_mi_dian_ji_shu_chu_dian_kuai___dian_pian__1.stl" />
        <mesh file="cj_003___right_wheel_foot_1__xiao_mi_dian_ji_shu_chu_dian_kuai___da_yin__1.stl" />
        <mesh file="cj_003___right_wheel_foot_1__ping_tou_m3_25_1.stl" />
        <mesh file="cj_003___right_wheel_foot_1__ping_tou_m3_25_2.stl" />
        <mesh file="cj_003___right_wheel_foot_1__ping_tou_m3_25_3.stl" />
        <mesh file="cj_003___right_wheel_foot_1__ping_tou_m3_25_4.stl" />
        <mesh file="cj_003___right_wheel_foot_1__ping_tou_m3_25_5.stl" />
        <mesh file="cj_003___right_wheel_foot_1__ping_tou_m3_25_6.stl" />
        <mesh file="cj_003___right_wheel_foot_1__ping_tou_m3_25_7.stl" />
        <mesh file="cj_003___right_wheel_foot_1__ping_tou_m3_25_8.stl" />
        <mesh file="cj_003___right_wheel_foot_1__ping_tou_m3_25_9.stl" />
        <mesh file="cj_003___right_wheel_foot_1__bei_tou_m4_35_1.stl" />
        <mesh file="cj_003___right_wheel_foot_1__bei_tou_m4_35_2.stl" />
        <mesh file="cj_003___right_wheel_foot_1__bei_tou_m4_35_3.stl" />
        <mesh file="cj_003___right_wheel_foot_1__bei_tou_m4_35_4.stl" />
        <mesh file="cj_003___right_wheel_foot_1__bei_tou_m4_35_5.stl" />
        <mesh file="cj_003___right_wheel_foot_1__bei_tou_m4_35_6.stl" />
        <mesh file="cj_003___right_wheel_foot_1__xiang_jiao_bao_lun__1.stl" />
        <mesh file="cj_003___right_wheel_foot_1__lun_ping_mian_gun_zhen_zhou_cheng__1.stl" />

    </asset>
    <!-- contype="2" conaffinity="2" -->

    <default>
        <default class="base_default">
            <geom contype="1" conaffinity="1" />
        </default>
        <default class="left_hip_default">
            <geom contype="0" conaffinity="0" />
        </default>
        <default class="left_thigh_default">
            <geom contype="1" conaffinity="1" />
        </default>
        <default class="left_calf_default">
            <geom contype="1" conaffinity="1" />
        </default>
        <default class="left_point_foot2_default">
            <geom contype="1" conaffinity="1" />
        </default>
        <default class="left_connect1_default">
            <geom contype="0" conaffinity="0" />
        </default>
        <default class="left_connect2_default">
            <geom contype="0" conaffinity="0" />
        </default>
        <default class="left_wheel_foot_default">
            <geom contype="1" conaffinity="1" />
        </default>

        <default class="right_hip_default">
            <geom contype="0" conaffinity="0" />
        </default>
        <default class="right_thigh_default">
            <geom contype="1" conaffinity="1" />
        </default>
        <default class="right_calf_default">
            <geom contype="1" conaffinity="1" />
        </default>
        <default class="right_point_foot2_default">
            <geom contype="1" conaffinity="1" />
        </default>
        <default class="right_connect1_default">
            <geom contype="0" conaffinity="0" />
        </default>
        <default class="right_connect2_default">
            <geom contype="0" conaffinity="0" />
        </default>
        <default class="right_wheel_foot_default">
            <geom contype="1" conaffinity="1" />
        </default>
    </default>

    <worldbody>

        <body name="base_body" pos="0 0 0.7">
            <!-- <freejoint /> -->
            <joint type="slide" axis="0 1 0" damping="0.0" frictionloss="0.0" stiffness="0.0"/>
            <joint type="slide" axis="0 0 1" damping="0.0" frictionloss="0.0" stiffness="0.0"/>
            <site name="imu" size="0.01" rgba="0 0 1 1"/>

            <geom type="mesh" mesh="cj_003___base_1_10103_liu_mian_luo_mu__1" mass="0.0022"
                class="base_default" />
            <geom type="mesh" mesh="cj_003___base_1_10103_liu_mian_luo_mu__2" mass="0.0022"
                class="base_default" />
            <geom type="mesh" mesh="cj_003___base_1_10103_liu_mian_luo_mu__3" mass="0.0022"
                class="base_default" />
            <geom type="mesh" mesh="cj_003___base_1_10103_liu_mian_luo_mu__4" mass="0.0022"
                class="base_default" />
            <geom type="mesh" mesh="cj_003___base_1_8009_rau_5005__wai_xing_chi_cun__20240809_1"
                mass="0.9450" class="base_default" />
            <geom type="mesh" mesh="cj_003___base_1_8009_rau_5005__wai_xing_chi_cun__20240809_2"
                mass="0.9450" class="base_default" />
            <geom type="mesh" mesh="cj_003___base_1_8840_jiao_jie__1" mass="0.0063"
                class="base_default" />
            <geom type="mesh" mesh="cj_003___base_1_8840_jiao_jie__2" mass="0.0063"
                class="base_default" />
            <geom type="mesh" mesh="cj_003___base_1_8840_jiao_jie__3" mass="0.0063"
                class="base_default" />
            <geom type="mesh" mesh="cj_003___base_1_8840_jiao_jie__4" mass="0.0063"
                class="base_default" />
            <geom type="mesh" mesh="cj_003___base_1_8840_jiao_jie__5" mass="0.0063"
                class="base_default" />
            <geom type="mesh" mesh="cj_003___base_1_8840_jiao_jie__6" mass="0.0063"
                class="base_default" />
            <geom type="mesh" mesh="cj_003___base_1_8840_jiao_jie__7" mass="0.0063"
                class="base_default" />
            <geom type="mesh" mesh="cj_003___base_1_8840_jiao_jie__8" mass="0.0063"
                class="base_default" />
            <geom type="mesh" mesh="cj_003___base_1_imu_gu_ding__1" mass="0.0045"
                class="base_default" />
            <geom type="mesh" mesh="cj_003___base_1_m5_40_shuang_tong_liu_jiao_luo_zhu__1"
                mass="0.0099" class="base_default" />
            <geom type="mesh" mesh="cj_003___base_1_m5_40_shuang_tong_liu_jiao_luo_zhu__2"
                mass="0.0099" class="base_default" />
            <geom type="mesh" mesh="cj_003___base_1_m5_40_shuang_tong_liu_jiao_luo_zhu__3"
                mass="0.0099" class="base_default" />
            <geom type="mesh" mesh="cj_003___base_1_m5_40_shuang_tong_liu_jiao_luo_zhu__4"
                mass="0.0099" class="base_default" />
            <geom type="mesh" mesh="cj_003___base_1_m5_40_shuang_tong_liu_jiao_luo_zhu__5"
                mass="0.0099" class="base_default" />
            <geom type="mesh" mesh="cj_003___base_1_m5_40_shuang_tong_liu_jiao_luo_zhu__6"
                mass="0.0099" class="base_default" />
            <geom type="mesh" mesh="cj_003___base_1_m5_8_0_8_dian_pian__1" mass="0.0001"
                class="base_default" />
            <geom type="mesh" mesh="cj_003___base_1_m5_8_0_8_dian_pian__2" mass="0.0001"
                class="base_default" />
            <geom type="mesh" mesh="cj_003___base_1_m5_8_0_8_dian_pian__3" mass="0.0001"
                class="base_default" />
            <geom type="mesh" mesh="cj_003___base_1_m5_8_0_8_dian_pian__4" mass="0.0001"
                class="base_default" />
            <geom type="mesh" mesh="cj_003___base_1_m5_8_0_8_dian_pian__5" mass="0.0001"
                class="base_default" />
            <geom type="mesh" mesh="cj_003___base_1_m5_8_0_8_dian_pian__6" mass="0.0001"
                class="base_default" />
            <geom type="mesh" mesh="cj_003___base_1__ping_tou_m4_10_1" mass="0.0009"
                class="base_default" />
            <geom type="mesh" mesh="cj_003___base_1__ping_tou_m4_10_10" mass="0.0009"
                class="base_default" />
            <geom type="mesh" mesh="cj_003___base_1__ping_tou_m4_10_11" mass="0.0009"
                class="base_default" />
            <geom type="mesh" mesh="cj_003___base_1__ping_tou_m4_10_12" mass="0.0009"
                class="base_default" />
            <geom type="mesh" mesh="cj_003___base_1__ping_tou_m4_10_2" mass="0.0009"
                class="base_default" />
            <geom type="mesh" mesh="cj_003___base_1__ping_tou_m4_10_3" mass="0.0009"
                class="base_default" />
            <geom type="mesh" mesh="cj_003___base_1__ping_tou_m4_10_4" mass="0.0009"
                class="base_default" />
            <geom type="mesh" mesh="cj_003___base_1__ping_tou_m4_10_5" mass="0.0009"
                class="base_default" />
            <geom type="mesh" mesh="cj_003___base_1__ping_tou_m4_10_6" mass="0.0009"
                class="base_default" />
            <geom type="mesh" mesh="cj_003___base_1__ping_tou_m4_10_7" mass="0.0009"
                class="base_default" />
            <geom type="mesh" mesh="cj_003___base_1__ping_tou_m4_10_8" mass="0.0009"
                class="base_default" />
            <geom type="mesh" mesh="cj_003___base_1__ping_tou_m4_10_9" mass="0.0009"
                class="base_default" />
            <geom type="mesh" mesh="cj_003___base_1__ji_shen_1_1" mass="0.1153" class="base_default" />
            <geom type="mesh" mesh="cj_003___base_1__ji_shen_3_1" mass="0.3415" class="base_default" />
            <geom type="mesh" mesh="cj_003___base_1__ji_shen_3_2" mass="0.3415" class="base_default" />
            <geom type="mesh" mesh="cj_003___base_1__ji_shen_4_1" mass="0.0917" class="base_default" />
            <geom type="mesh" mesh="cj_003___base_1__bei_tou_m3_14_1" mass="0.0001"
                class="base_default" />
            <geom type="mesh" mesh="cj_003___base_1__bei_tou_m3_14_10" mass="0.0001"
                class="base_default" />
            <geom type="mesh" mesh="cj_003___base_1__bei_tou_m3_14_11" mass="0.0001"
                class="base_default" />
            <geom type="mesh" mesh="cj_003___base_1__bei_tou_m3_14_12" mass="0.0001"
                class="base_default" />
            <geom type="mesh" mesh="cj_003___base_1__bei_tou_m3_14_13" mass="0.0001"
                class="base_default" />
            <geom type="mesh" mesh="cj_003___base_1__bei_tou_m3_14_14" mass="0.0001"
                class="base_default" />
            <geom type="mesh" mesh="cj_003___base_1__bei_tou_m3_14_15" mass="0.0001"
                class="base_default" />
            <geom type="mesh" mesh="cj_003___base_1__bei_tou_m3_14_16" mass="0.0001"
                class="base_default" />
            <geom type="mesh" mesh="cj_003___base_1__bei_tou_m3_14_17" mass="0.0001"
                class="base_default" />
            <geom type="mesh" mesh="cj_003___base_1__bei_tou_m3_14_18" mass="0.0001"
                class="base_default" />
            <geom type="mesh" mesh="cj_003___base_1__bei_tou_m3_14_19" mass="0.0001"
                class="base_default" />
            <geom type="mesh" mesh="cj_003___base_1__bei_tou_m3_14_2" mass="0.0001"
                class="base_default" />
            <geom type="mesh" mesh="cj_003___base_1__bei_tou_m3_14_20" mass="0.0001"
                class="base_default" />
            <geom type="mesh" mesh="cj_003___base_1__bei_tou_m3_14_21" mass="0.0001"
                class="base_default" />
            <geom type="mesh" mesh="cj_003___base_1__bei_tou_m3_14_22" mass="0.0001"
                class="base_default" />
            <geom type="mesh" mesh="cj_003___base_1__bei_tou_m3_14_23" mass="0.0001"
                class="base_default" />
            <geom type="mesh" mesh="cj_003___base_1__bei_tou_m3_14_24" mass="0.0001"
                class="base_default" />
            <geom type="mesh" mesh="cj_003___base_1__bei_tou_m3_14_25" mass="0.0001"
                class="base_default" />
            <geom type="mesh" mesh="cj_003___base_1__bei_tou_m3_14_26" mass="0.0001"
                class="base_default" />
            <geom type="mesh" mesh="cj_003___base_1__bei_tou_m3_14_27" mass="0.0001"
                class="base_default" />
            <geom type="mesh" mesh="cj_003___base_1__bei_tou_m3_14_28" mass="0.0001"
                class="base_default" />
            <geom type="mesh" mesh="cj_003___base_1__bei_tou_m3_14_29" mass="0.0001"
                class="base_default" />
            <geom type="mesh" mesh="cj_003___base_1__bei_tou_m3_14_3" mass="0.0001"
                class="base_default" />
            <geom type="mesh" mesh="cj_003___base_1__bei_tou_m3_14_30" mass="0.0001"
                class="base_default" />
            <geom type="mesh" mesh="cj_003___base_1__bei_tou_m3_14_31" mass="0.0001"
                class="base_default" />
            <geom type="mesh" mesh="cj_003___base_1__bei_tou_m3_14_32" mass="0.0001"
                class="base_default" />
            <geom type="mesh" mesh="cj_003___base_1__bei_tou_m3_14_4" mass="0.0001"
                class="base_default" />
            <geom type="mesh" mesh="cj_003___base_1__bei_tou_m3_14_5" mass="0.0001"
                class="base_default" />
            <geom type="mesh" mesh="cj_003___base_1__bei_tou_m3_14_6" mass="0.0001"
                class="base_default" />
            <geom type="mesh" mesh="cj_003___base_1__bei_tou_m3_14_7" mass="0.0001"
                class="base_default" />
            <geom type="mesh" mesh="cj_003___base_1__bei_tou_m3_14_8" mass="0.0001"
                class="base_default" />
            <geom type="mesh" mesh="cj_003___base_1__bei_tou_m3_14_9" mass="0.0001"
                class="base_default" />
            <geom type="mesh" mesh="cj_003___base_1__bei_tou_m3_6_1" mass="0.0006"
                class="base_default" />
            <geom type="mesh" mesh="cj_003___base_1__bei_tou_m3_6_2" mass="0.0006"
                class="base_default" />
            <geom type="mesh" mesh="cj_003___base_1__bei_tou_m3_6_3" mass="0.0006"
                class="base_default" />
            <geom type="mesh" mesh="cj_003___base_1__bei_tou_m3_6_4" mass="0.0006"
                class="base_default" />
            <geom type="mesh" mesh="cj_003___base_1__bei_tou_m3_6_5" mass="0.0006"
                class="base_default" />
            <geom type="mesh" mesh="cj_003___base_1__bei_tou_m3_6_6" mass="0.0006"
                class="base_default" />
            <geom type="mesh" mesh="cj_003___base_1__bei_tou_m3_6_7" mass="0.0006"
                class="base_default" />
            <geom type="mesh" mesh="cj_003___base_1__bei_tou_m3_6_8" mass="0.0006"
                class="base_default" />
            <geom type="mesh" mesh="cj_003___base_1__bei_tou_m4_8_1" mass="0.0015"
                class="base_default" />
            <geom type="mesh" mesh="cj_003___base_1__bei_tou_m4_8_11" mass="0.0015"
                class="base_default" />
            <geom type="mesh" mesh="cj_003___base_1__bei_tou_m4_8_12" mass="0.0015"
                class="base_default" />
            <geom type="mesh" mesh="cj_003___base_1__bei_tou_m4_8_2" mass="0.0015"
                class="base_default" />
            <geom type="mesh" mesh="cj_003___base_1__bei_tou_m4_8_3" mass="0.0015"
                class="base_default" />
            <geom type="mesh" mesh="cj_003___base_1__bei_tou_m4_8_4" mass="0.0015"
                class="base_default" />
            <geom type="mesh" mesh="cj_003___base_1__bei_tou_m4_8_5" mass="0.0015"
                class="base_default" />
            <geom type="mesh" mesh="cj_003___base_1__bei_tou_m4_8_6" mass="0.0015"
                class="base_default" />
            <geom type="mesh" mesh="cj_003___base_1__bei_tou_m4_8_7" mass="0.0015"
                class="base_default" />
            <geom type="mesh" mesh="cj_003___base_1__bei_tou_m4_8_9" mass="0.0015"
                class="base_default" />
            <geom type="mesh" mesh="cj_003___base_1__bei_tou_m5_12_1" mass="0.0031"
                class="base_default" />
            <geom type="mesh" mesh="cj_003___base_1__bei_tou_m5_12_10" mass="0.0031"
                class="base_default" />
            <geom type="mesh" mesh="cj_003___base_1__bei_tou_m5_12_11" mass="0.0031"
                class="base_default" />
            <geom type="mesh" mesh="cj_003___base_1__bei_tou_m5_12_12" mass="0.0031"
                class="base_default" />
            <geom type="mesh" mesh="cj_003___base_1__bei_tou_m5_12_2" mass="0.0031"
                class="base_default" />
            <geom type="mesh" mesh="cj_003___base_1__bei_tou_m5_12_3" mass="0.0031"
                class="base_default" />
            <geom type="mesh" mesh="cj_003___base_1__bei_tou_m5_12_4" mass="0.0031"
                class="base_default" />
            <geom type="mesh" mesh="cj_003___base_1__bei_tou_m5_12_5" mass="0.0031"
                class="base_default" />
            <geom type="mesh" mesh="cj_003___base_1__bei_tou_m5_12_6" mass="0.0031"
                class="base_default" />
            <geom type="mesh" mesh="cj_003___base_1__bei_tou_m5_12_7" mass="0.0031"
                class="base_default" />
            <geom type="mesh" mesh="cj_003___base_1__bei_tou_m5_12_8" mass="0.0031"
                class="base_default" />
            <geom type="mesh" mesh="cj_003___base_1__bei_tou_m5_12_9" mass="0.0031"
                class="base_default" />

            <body name="left_hip_body" pos="-0.03 0.08 -0.159">
                <joint name="left_hip_joint" type="hinge" axis="1 0 0" />
                <geom type="mesh" mesh="cj_003___left_hip_1_6621_jiao_jie__1" mass="0.0016"
                    class="left_hip_default" />
                <geom type="mesh" mesh="cj_003___left_hip_1_6621_jiao_jie__2" mass="0.0016"
                    class="left_hip_default" />
                <geom type="mesh" mesh="cj_003___left_hip_1_6621_jiao_jie__3" mass="0.0016"
                    class="left_hip_default" />
                <geom type="mesh" mesh="cj_003___left_hip_1_6621_jiao_jie__4" mass="0.0016"
                    class="left_hip_default" />
                <geom type="mesh" mesh="cj_003___left_hip_1_6621_jiao_jie__5" mass="0.0016"
                    class="left_hip_default" />
                <geom type="mesh" mesh="cj_003___left_hip_1_6621_jiao_jie__6" mass="0.0016"
                    class="left_hip_default" />
                <geom type="mesh"
                    mesh="cj_003___left_hip_1_8009_rau_5005__wai_xing_chi_cun__20240809_1"
                    mass="0.9450" class="left_hip_default" />
                <geom type="mesh" mesh="cj_003___left_hip_1__da_tui_dian_ji_gu_ding_1_1"
                    mass="0.0286" class="left_hip_default" />
                <geom type="mesh" mesh="cj_003___left_hip_1__da_tui_dian_ji_gu_ding_2_1"
                    mass="0.0396" class="left_hip_default" />
                <geom type="mesh" mesh="cj_003___left_hip_1__da_tui_dian_ji_gu_ding_3_1"
                    mass="0.0363" class="left_hip_default" />
                <geom type="mesh" mesh="cj_003___left_hip_1__da_tui_dian_ji_gu_ding_4_1"
                    mass="0.0057" class="left_hip_default" />
                <geom type="mesh" mesh="cj_003___left_hip_1__da_tui_dian_ji_gu_ding_4_2"
                    mass="0.0057" class="left_hip_default" />
                <geom type="mesh" mesh="cj_003___left_hip_1__da_tui_dian_ji_gu_ding_5_1"
                    mass="0.0035" class="left_hip_default" />
                <geom type="mesh" mesh="cj_003___left_hip_1__ping_tou_m3_10_12" mass="0.0006"
                    class="left_hip_default" />
                <geom type="mesh" mesh="cj_003___left_hip_1__ping_tou_m3_10_13" mass="0.0006"
                    class="left_hip_default" />
                <geom type="mesh" mesh="cj_003___left_hip_1__ping_tou_m3_10_15" mass="0.0006"
                    class="left_hip_default" />
                <geom type="mesh" mesh="cj_003___left_hip_1__ping_tou_m3_10_16" mass="0.0006"
                    class="left_hip_default" />
                <geom type="mesh" mesh="cj_003___left_hip_1__ping_tou_m3_10_2" mass="0.0006"
                    class="left_hip_default" />
                <geom type="mesh" mesh="cj_003___left_hip_1__ping_tou_m3_10_3" mass="0.0006"
                    class="left_hip_default" />
                <geom type="mesh" mesh="cj_003___left_hip_1__ping_tou_m3_10_7" mass="0.0006"
                    class="left_hip_default" />
                <geom type="mesh" mesh="cj_003___left_hip_1__ping_tou_m3_10_8" mass="0.0006"
                    class="left_hip_default" />
                <geom type="mesh" mesh="cj_003___left_hip_1__ping_tou_m3_10_9" mass="0.0006"
                    class="left_hip_default" />
                <geom type="mesh" mesh="cj_003___left_hip_1__ping_tou_m3_16_1" mass="0.0008"
                    class="left_hip_default" />
                <geom type="mesh" mesh="cj_003___left_hip_1__ping_tou_m3_16_2" mass="0.0008"
                    class="left_hip_default" />
                <geom type="mesh" mesh="cj_003___left_hip_1__ping_tou_m3_16_3" mass="0.0008"
                    class="left_hip_default" />
                <geom type="mesh" mesh="cj_003___left_hip_1__ping_tou_m3_16_4" mass="0.0008"
                    class="left_hip_default" />
                <geom type="mesh" mesh="cj_003___left_hip_1__ping_tou_m4_10_1" mass="0.0009"
                    class="left_hip_default" />
                <geom type="mesh" mesh="cj_003___left_hip_1__ping_tou_m4_10_3" mass="0.0009"
                    class="left_hip_default" />
                <geom type="mesh" mesh="cj_003___left_hip_1__ping_tou_m4_10_4" mass="0.0009"
                    class="left_hip_default" />
                <geom type="mesh" mesh="cj_003___left_hip_1__ping_tou_m4_10_5" mass="0.0009"
                    class="left_hip_default" />
                <geom type="mesh" mesh="cj_003___left_hip_1__ping_tou_m4_10_6" mass="0.0009"
                    class="left_hip_default" />
                <geom type="mesh" mesh="cj_003___left_hip_1__ping_tou_m5_14_1" mass="0.0021"
                    class="left_hip_default" />
                <geom type="mesh" mesh="cj_003___left_hip_1__ping_tou_m5_14_2" mass="0.0021"
                    class="left_hip_default" />
                <geom type="mesh" mesh="cj_003___left_hip_1__ping_tou_m5_14_3" mass="0.0021"
                    class="left_hip_default" />
                <geom type="mesh" mesh="cj_003___left_hip_1__ping_tou_m5_14_4" mass="0.0021"
                    class="left_hip_default" />
                <geom type="mesh" mesh="cj_003___left_hip_1__ping_tou_m5_14_5" mass="0.0021"
                    class="left_hip_default" />
                <geom type="mesh" mesh="cj_003___left_hip_1__ping_tou_m5_14_6" mass="0.0021"
                    class="left_hip_default" />
                <geom type="mesh" mesh="cj_003___left_hip_1__bei_tou_m3_12_1" mass="0.0009"
                    class="left_hip_default" />
                <geom type="mesh" mesh="cj_003___left_hip_1__bei_tou_m3_12_2" mass="0.0009"
                    class="left_hip_default" />
                <geom type="mesh" mesh="cj_003___left_hip_1__bei_tou_m3_12_3" mass="0.0009"
                    class="left_hip_default" />
                <geom type="mesh" mesh="cj_003___left_hip_1__bei_tou_m3_12_4" mass="0.0009"
                    class="left_hip_default" />
                <geom type="mesh" mesh="cj_003___left_hip_1__bei_tou_m3_12_5" mass="0.0009"
                    class="left_hip_default" />
                <geom type="mesh" mesh="cj_003___left_hip_1__bei_tou_m3_12_6" mass="0.0009"
                    class="left_hip_default" />
                <geom type="mesh" mesh="cj_003___left_hip_1__bei_tou_m3_12_7" mass="0.0009"
                    class="left_hip_default" />
                <geom type="mesh" mesh="cj_003___left_hip_1__bei_tou_m3_12_8" mass="0.0009"
                    class="left_hip_default" />
                <geom type="mesh" mesh="cj_003___left_hip_1__bei_tou_m4_8_1" mass="0.0015"
                    class="left_hip_default" />
                <geom type="mesh" mesh="cj_003___left_hip_1__bei_tou_m4_8_2" mass="0.0015"
                    class="left_hip_default" />
                <geom type="mesh" mesh="cj_003___left_hip_1__bei_tou_m4_8_3" mass="0.0015"
                    class="left_hip_default" />
                <geom type="mesh" mesh="cj_003___left_hip_1__bei_tou_m4_8_4" mass="0.0015"
                    class="left_hip_default" />
                <geom type="mesh" mesh="cj_003___left_hip_1__bei_tou_m4_8_5" mass="0.0015"
                    class="left_hip_default" />
                <geom type="mesh" mesh="cj_003___left_hip_1__bei_tou_m4_8_6" mass="0.0015"
                    class="left_hip_default" />

                <body name="left_thigh_body" pos="-0.059 0.0306 0">
                    <joint name="left_thigh_joint" type="hinge" axis="0 1 0" />
                    <geom type="mesh"
                        mesh="cj_003___left_thigh_2_8009_rau_5005__wai_xing_chi_cun__20240809_1"
                        mass="0.9450" class="left_thigh_default" />
                    <geom type="mesh"
                        mesh="cj_003___left_thigh_2_m5_40_shuang_tong_liu_jiao_luo_zhu__1"
                        mass="0.0099" class="left_thigh_default" />
                    <geom type="mesh"
                        mesh="cj_003___left_thigh_2_m5_40_shuang_tong_liu_jiao_luo_zhu__2"
                        mass="0.0099" class="left_thigh_default" />
                    <geom type="mesh"
                        mesh="cj_003___left_thigh_2_m5_40_shuang_tong_liu_jiao_luo_zhu__3"
                        mass="0.0099" class="left_thigh_default" />
                    <geom type="mesh" mesh="cj_003___left_thigh_2_m5_8_0_8_dian_pian__1"
                        mass="0.0001" class="left_thigh_default" />
                    <geom type="mesh" mesh="cj_003___left_thigh_2_m5_8_0_8_dian_pian__2"
                        mass="0.0001" class="left_thigh_default" />
                    <geom type="mesh" mesh="cj_003___left_thigh_2_m5_8_0_8_dian_pian__3"
                        mass="0.0001" class="left_thigh_default" />
                    <geom type="mesh" mesh="cj_003___left_thigh_2__wai_liu_jiao_m4_22_1"
                        mass="0.0024" class="left_thigh_default" />
                    <geom type="mesh" mesh="cj_003___left_thigh_2__wai_liu_jiao_m4_22_2"
                        mass="0.0024" class="left_thigh_default" />
                    <geom type="mesh" mesh="cj_003___left_thigh_2__wai_liu_jiao_m4_22_3"
                        mass="0.0024" class="left_thigh_default" />
                    <geom type="mesh" mesh="cj_003___left_thigh_2__wai_liu_jiao_m4_22_4"
                        mass="0.0024" class="left_thigh_default" />
                    <geom type="mesh" mesh="cj_003___left_thigh_2__wai_liu_jiao_m4_22_5"
                        mass="0.0024" class="left_thigh_default" />
                    <geom type="mesh" mesh="cj_003___left_thigh_2__da_tui_dian_ji_gu_ding_5_1"
                        mass="0.0035" class="left_thigh_default" />
                    <geom type="mesh"
                        mesh="cj_003___left_thigh_2__da_tui_dian_ji_gu_ding_dian_kuai__1"
                        mass="0.0205" class="left_thigh_default" />
                    <geom type="mesh"
                        mesh="cj_003___left_thigh_2__da_tui_dian_ji_gu_ding_dian_kuai__2"
                        mass="0.0205" class="left_thigh_default" />
                    <geom type="mesh" mesh="cj_003___left_thigh_2__da_tui_di_yi_ceng__1"
                        mass="0.1100" class="left_thigh_default" />
                    <geom type="mesh" mesh="cj_003___left_thigh_2__da_tui_di_er_ceng__1"
                        mass="0.1067" class="left_thigh_default" />
                    <geom type="mesh" mesh="cj_003___left_thigh_2__da_tui_xi_guan_jie_dian_kuai__1"
                        mass="0.0053" class="left_thigh_default" />
                    <geom type="mesh" mesh="cj_003___left_thigh_2__da_tui_xi_guan_jie_dian_kuai__2"
                        mass="0.0053" class="left_thigh_default" />
                    <geom type="mesh"
                        mesh="cj_003___left_thigh_2__xiao_tui_dian_ji_lian_jie___lv_he_jin__1"
                        mass="0.0720" class="left_thigh_default" />
                    <geom type="mesh" mesh="cj_003___left_thigh_2__ping_tou_m5_22_1" mass="0.0031"
                        class="left_thigh_default" />
                    <geom type="mesh" mesh="cj_003___left_thigh_2__ping_tou_m5_22_2" mass="0.0031"
                        class="left_thigh_default" />
                    <geom type="mesh" mesh="cj_003___left_thigh_2__ping_tou_m5_22_3" mass="0.0031"
                        class="left_thigh_default" />
                    <geom type="mesh" mesh="cj_003___left_thigh_2__ping_tou_m5_22_4" mass="0.0031"
                        class="left_thigh_default" />
                    <geom type="mesh" mesh="cj_003___left_thigh_2__ping_tou_m5_22_5" mass="0.0031"
                        class="left_thigh_default" />
                    <geom type="mesh" mesh="cj_003___left_thigh_2__ping_tou_m5_22_6" mass="0.0031"
                        class="left_thigh_default" />
                    <geom type="mesh" mesh="cj_003___left_thigh_2__bei_tou_m3_55_1" mass="0.0027"
                        class="left_thigh_default" />
                    <geom type="mesh" mesh="cj_003___left_thigh_2__bei_tou_m3_55_2" mass="0.0027"
                        class="left_thigh_default" />
                    <geom type="mesh" mesh="cj_003___left_thigh_2__bei_tou_m3_55_3" mass="0.0027"
                        class="left_thigh_default" />
                    <geom type="mesh" mesh="cj_003___left_thigh_2__bei_tou_m3_55_4" mass="0.0027"
                        class="left_thigh_default" />
                    <geom type="mesh" mesh="cj_003___left_thigh_2__bei_tou_m3_55_5" mass="0.0027"
                        class="left_thigh_default" />
                    <geom type="mesh" mesh="cj_003___left_thigh_2__bei_tou_m3_55_6" mass="0.0027"
                        class="left_thigh_default" />
                    <geom type="mesh" mesh="cj_003___left_thigh_2__bei_tou_m4_10_1" mass="0.0001"
                        class="left_thigh_default" />
                    <geom type="mesh" mesh="cj_003___left_thigh_2__bei_tou_m4_10_2" mass="0.0001"
                        class="left_thigh_default" />
                    <geom type="mesh" mesh="cj_003___left_thigh_2__bei_tou_m4_10_3" mass="0.0001"
                        class="left_thigh_default" />
                    <geom type="mesh" mesh="cj_003___left_thigh_2__bei_tou_m4_10_4" mass="0.0001"
                        class="left_thigh_default" />
                    <geom type="mesh" mesh="cj_003___left_thigh_2__bei_tou_m4_10_5" mass="0.0001"
                        class="left_thigh_default" />
                    <geom type="mesh" mesh="cj_003___left_thigh_2__bei_tou_m4_10_6" mass="0.0001"
                        class="left_thigh_default" />
                    <geom type="mesh" mesh="cj_003___left_thigh_2__bei_tou_m5_12_1" mass="0.0031"
                        class="left_thigh_default" />
                    <geom type="mesh" mesh="cj_003___left_thigh_2__bei_tou_m5_12_2" mass="0.0031"
                        class="left_thigh_default" />
                    <geom type="mesh" mesh="cj_003___left_thigh_2__bei_tou_m5_12_3" mass="0.0031"
                        class="left_thigh_default" />
                    <geom type="mesh" mesh="cj_003___left_thigh_2__bei_tou_m5_12_4" mass="0.0031"
                        class="left_thigh_default" />
                    <geom type="mesh" mesh="cj_003___left_thigh_2__bei_tou_m5_12_5" mass="0.0031"
                        class="left_thigh_default" />
                    <geom type="mesh" mesh="cj_003___left_thigh_2__bei_tou_m5_12_6" mass="0.0031"
                        class="left_thigh_default" />
                    <geom type="mesh" mesh="cj_003___left_thigh_2__xi_guan_jie_zhou_cheng__1"
                        mass="0.2920" class="left_thigh_default" />

                    <body name="left_calf_body" pos="0 0.0489 -0.2">
                        <joint name="left_calf_joint" type="hinge" axis="0 1 0"/>
                        <site name="left_connect1" size="0.001" rgba="0 1 0 1"
                            pos="-0.01042 0.04475 0.05909" />
                        <geom type="mesh" mesh="cj_003___left_calf_1_m3_fang_hua_luo_mu__1"
                            mass="0.0001" class="left_calf_default" />
                        <geom type="mesh" mesh="cj_003___left_calf_1_m3_fang_hua_luo_mu__2"
                            mass="0.0001" class="left_calf_default" />
                        <geom type="mesh" mesh="cj_003___left_calf_1_m3_fang_hua_luo_mu__3"
                            mass="0.0001" class="left_calf_default" />
                        <geom type="mesh" mesh="cj_003___left_calf_1_m3_fang_hua_luo_mu__4"
                            mass="0.0001" class="left_calf_default" />
                        <geom type="mesh" mesh="cj_003___left_calf_1_m3_fang_hua_luo_mu__5"
                            mass="0.0001" class="left_calf_default" />
                        <geom type="mesh" mesh="cj_003___left_calf_1_m3_fang_hua_luo_mu__6"
                            mass="0.0001" class="left_calf_default" />
                        <geom type="mesh"
                            mesh="cj_003___left_calf_1_m4_12_shuang_tong_liu_jiao_luo_zhu__1"
                            mass="0.0019" class="left_calf_default" />
                        <geom type="mesh"
                            mesh="cj_003___left_calf_1_m4_12_shuang_tong_liu_jiao_luo_zhu__2"
                            mass="0.0019" class="left_calf_default" />
                        <geom type="mesh" mesh="cj_003___left_calf_1_m4_fang_hua_luo_mu__1"
                            mass="0.0001" class="left_calf_default" />
                        <geom type="mesh" mesh="cj_003___left_calf_1_m4_fang_hua_luo_mu__2"
                            mass="0.0001" class="left_calf_default" />
                        <geom type="mesh" mesh="cj_003___left_calf_1_m4_fang_hua_luo_mu__3"
                            mass="0.0001" class="left_calf_default" />
                        <geom type="mesh" mesh="cj_003___left_calf_1_m4_fang_hua_luo_mu__4"
                            mass="0.0001" class="left_calf_default" />
                        <geom type="mesh" mesh="cj_003___left_calf_1_m4_fang_hua_luo_mu__5"
                            mass="0.0001" class="left_calf_default" />
                        <geom type="mesh" mesh="cj_003___left_calf_1_m4_fang_hua_luo_mu__6"
                            mass="0.0001" class="left_calf_default" />
                        <geom type="mesh" mesh="cj_003___left_calf_1_m4_fang_hua_luo_mu__7"
                            mass="0.0001" class="left_calf_default" />
                        <geom type="mesh" mesh="cj_003___left_calf_1_m4_fang_hua_luo_mu__8"
                            mass="0.0001" class="left_calf_default" />
                        <geom type="mesh" mesh="cj_003___left_calf_1_m5_fang_hua_luo_mu__1"
                            mass="0.0001" class="left_calf_default" />
                        <geom type="mesh" mesh="cj_003___left_calf_1__sai_da_luo_si_m6_50_5_1"
                            mass="0.0144" class="left_calf_default" />
                        <geom type="mesh" mesh="cj_003___left_calf_1__xiao_tui__1" mass="0.0720"
                            class="left_calf_default" />
                        <geom type="mesh" mesh="cj_003___left_calf_1__xiao_tui__2" mass="0.0720"
                            class="left_calf_default" />
                        <geom type="mesh" mesh="cj_003___left_calf_1__ping_tou_m4_30_1"
                            mass="0.0025" class="left_calf_default" />
                        <geom type="mesh" mesh="cj_003___left_calf_1__ping_tou_m4_30_2"
                            mass="0.0025" class="left_calf_default" />
                        <geom type="mesh" mesh="cj_003___left_calf_1__ping_tou_m4_30_3"
                            mass="0.0025" class="left_calf_default" />
                        <geom type="mesh" mesh="cj_003___left_calf_1__ping_tou_m4_30_4"
                            mass="0.0025" class="left_calf_default" />
                        <geom type="mesh" mesh="cj_003___left_calf_1__ping_tou_m4_30_5"
                            mass="0.0025" class="left_calf_default" />
                        <geom type="mesh" mesh="cj_003___left_calf_1__ping_tou_m4_30_6"
                            mass="0.0025" class="left_calf_default" />
                        <geom type="mesh" mesh="cj_003___left_calf_1__ping_tou_m4_30_7"
                            mass="0.0025" class="left_calf_default" />
                        <geom type="mesh" mesh="cj_003___left_calf_1__ping_tou_m4_30_8"
                            mass="0.0025" class="left_calf_default" />
                        <geom type="mesh" mesh="cj_003___left_calf_1__bei_tou_m3_10_1" mass="0.0008"
                            class="left_calf_default" />
                        <geom type="mesh" mesh="cj_003___left_calf_1__bei_tou_m3_10_2" mass="0.0008"
                            class="left_calf_default" />
                        <geom type="mesh" mesh="cj_003___left_calf_1__bei_tou_m3_10_3" mass="0.0008"
                            class="left_calf_default" />
                        <geom type="mesh" mesh="cj_003___left_calf_1__bei_tou_m3_10_4" mass="0.0008"
                            class="left_calf_default" />
                        <geom type="mesh" mesh="cj_003___left_calf_1__bei_tou_m3_25_1" mass="0.0015"
                            class="left_calf_default" />
                        <geom type="mesh" mesh="cj_003___left_calf_1__bei_tou_m3_25_2" mass="0.0015"
                            class="left_calf_default" />
                        <geom type="mesh" mesh="cj_003___left_calf_1__bei_tou_m3_25_3" mass="0.0015"
                            class="left_calf_default" />
                        <geom type="mesh" mesh="cj_003___left_calf_1__bei_tou_m3_25_4" mass="0.0015"
                            class="left_calf_default" />
                        <geom type="mesh" mesh="cj_003___left_calf_1__bei_tou_m3_25_5" mass="0.0015"
                            class="left_calf_default" />
                        <geom type="mesh" mesh="cj_003___left_calf_1__bei_tou_m3_25_6" mass="0.0015"
                            class="left_calf_default" />
                        <geom type="mesh"
                            mesh="cj_003___left_calf_1__xi_guan_jie_xiao_tui_zhi_cheng_zhu__1"
                            mass="0.0018" class="left_calf_default" />
                        <geom type="mesh"
                            mesh="cj_003___left_calf_1__xi_guan_jie_lian_gan_dian_zhu__1"
                            mass="0.0331" class="left_calf_default" />

                        <geom type="mesh" mesh="cj_003___left_wheel_foot_1__xiao_mi_dian_ji__1"
                            mass="0.0001" class="left_calf_default" pos="0.03994 0.013 -0.22651" />
                        <geom type="mesh" mesh="cj_003___left_wheel_foot_1__ping_tou_m3_25_1"
                            mass="0.0015" class="left_calf_default" pos="0.03994 0.013 -0.22651" />
                        <geom type="mesh" mesh="cj_003___left_wheel_foot_1__ping_tou_m3_25_2"
                            mass="0.0015" class="left_calf_default" pos="0.03994 0.013 -0.22651" />
                        <geom type="mesh" mesh="cj_003___left_wheel_foot_1__ping_tou_m3_25_3"
                            mass="0.0015" class="left_calf_default" pos="0.03994 0.013 -0.22651" />
                        <geom type="mesh" mesh="cj_003___left_wheel_foot_1__ping_tou_m3_25_4"
                            mass="0.0015" class="left_calf_default" pos="0.03994 0.013 -0.22651" />
                        <geom type="mesh" mesh="cj_003___left_wheel_foot_1__ping_tou_m3_25_5"
                            mass="0.0015" class="left_calf_default" pos="0.03994 0.013 -0.22651" />
                        <geom type="mesh" mesh="cj_003___left_wheel_foot_1__ping_tou_m3_25_6"
                            mass="0.0015" class="left_calf_default" pos="0.03994 0.013 -0.22651" />
                        <geom type="mesh" mesh="cj_003___left_wheel_foot_1__ping_tou_m3_25_7"
                            mass="0.0015" class="left_calf_default" pos="0.03994 0.013 -0.22651" />
                        <geom type="mesh" mesh="cj_003___left_wheel_foot_1__ping_tou_m3_25_8"
                            mass="0.0015" class="left_calf_default" pos="0.03994 0.013 -0.22651" />
                        <geom type="mesh" mesh="cj_003___left_wheel_foot_1__ping_tou_m3_25_9"
                            mass="0.0015" class="left_calf_default" pos="0.03994 0.013 -0.22651" />
                        <geom type="mesh"
                            mesh="cj_003___left_wheel_foot_1__xiao_mi_shen_gou_qiu_gu_ding__1"
                            mass="0.0106" class="left_calf_default" pos="0.03994 0.013 -0.22651" />

                        <body name="left_point_foot2" pos="0 0 0">


                            <geom type="mesh" mesh="cj_003___left_point_foot2_1__lun_zu_mo_duan__1"
                                mass="0.0525" class="left_point_foot2_default" />
                            <geom type="mesh" mesh="cj_003___left_point_foot2_1__lun_zu_mo_duan__2"
                                mass="0.0525" class="left_point_foot2_default" />
                            <geom type="mesh"
                                mesh="cj_003___left_point_foot2_1__lun_zu_mo_duan___shen_gou_qiu_gu_ding__1"
                                mass="0.0525" class="left_point_foot2_default" />

                            <body name="left_wheel_foot_body" pos="0.03994 0.013 -0.22651">
                                <joint name="left_wheel_joint" type="hinge" axis="0 1 0" />
                                <geom type="mesh" mesh="cj_003___left_wheel_foot_1_220_lun_gu__1"
                                    mass="0.3844" class="left_wheel_foot_default" />


                                <geom type="mesh"
                                    mesh="cj_003___left_wheel_foot_1__xiao_mi_dian_ji_shen_gou_qiu_zhou_cheng__1"
                                    mass="0.0289" class="left_wheel_foot_default" />
                                <geom type="mesh"
                                    mesh="cj_003___left_wheel_foot_1__xiao_mi_dian_ji_shu_chu_dian_kuai___ya_ban__1"
                                    mass="0.0094" class="left_wheel_foot_default" />
                                <geom type="mesh"
                                    mesh="cj_003___left_wheel_foot_1__xiao_mi_dian_ji_shu_chu_dian_kuai___dian_pian__1"
                                    mass="0.0070" class="left_wheel_foot_default" />
                                <geom type="mesh"
                                    mesh="cj_003___left_wheel_foot_1__xiao_mi_dian_ji_shu_chu_dian_kuai___da_yin__1"
                                    mass="0.0053" class="left_wheel_foot_default" />

                                <geom type="mesh" mesh="cj_003___left_wheel_foot_1__bei_tou_m4_35_1"
                                    mass="0.0035" class="left_wheel_foot_default" />
                                <geom type="mesh" mesh="cj_003___left_wheel_foot_1__bei_tou_m4_35_2"
                                    mass="0.0035" class="left_wheel_foot_default" />
                                <geom type="mesh" mesh="cj_003___left_wheel_foot_1__bei_tou_m4_35_3"
                                    mass="0.0035" class="left_wheel_foot_default" />
                                <geom type="mesh" mesh="cj_003___left_wheel_foot_1__bei_tou_m4_35_4"
                                    mass="0.0035" class="left_wheel_foot_default" />
                                <geom type="mesh" mesh="cj_003___left_wheel_foot_1__bei_tou_m4_35_5"
                                    mass="0.0035" class="left_wheel_foot_default" />
                                <geom type="mesh" mesh="cj_003___left_wheel_foot_1__bei_tou_m4_35_6"
                                    mass="0.0035" class="left_wheel_foot_default" />
                                <geom type="mesh"
                                    mesh="cj_003___left_wheel_foot_1__xiang_jiao_bao_lun__1"
                                    mass="0.4817" class="left_wheel_foot_default" />
                                <geom type="mesh"
                                    mesh="cj_003___left_wheel_foot_1__lun_ping_mian_gun_zhen_zhou_cheng__1"
                                    mass="0.0384" class="left_wheel_foot_default" />
                            </body>
                        </body>
                    </body>

                    <!--  -->
                    <body name="left_connect1_body" pos="0 0.0815 0">
                        <joint name="left_connect1_joint" type="hinge" axis="0 1 0" range="-2 0" />
                        <geom type="mesh" mesh="cj_003___left_connect1_1_8009_lian_gan__1"
                            mass="0.9450" class="left_connect1_default" />
                        <geom type="mesh" mesh="cj_003___left_connect1_1_m5_fang_hua_luo_mu__1"
                            mass="0.0001" class="left_connect1_default" />
                        <geom type="mesh" mesh="cj_003___left_connect1_1__sai_da_luo_si_m6_12_5_1"
                            mass="0.0063" class="left_connect1_default" />
                        <geom type="mesh" mesh="cj_003___left_connect1_1__ping_tou_m5_12_1"
                            mass="0.0001" class="left_connect1_default" />
                        <geom type="mesh" mesh="cj_003___left_connect1_1__ping_tou_m5_12_2"
                            mass="0.0001" class="left_connect1_default" />
                        <geom type="mesh" mesh="cj_003___left_connect1_1__ping_tou_m5_12_3"
                            mass="0.0001" class="left_connect1_default" />
                        <geom type="mesh" mesh="cj_003___left_connect1_1__ping_tou_m5_12_4"
                            mass="0.0001" class="left_connect1_default" />
                        <geom type="mesh" mesh="cj_003___left_connect1_1__ping_tou_m5_12_5"
                            mass="0.0001" class="left_connect1_default" />
                        <geom type="mesh" mesh="cj_003___left_connect1_1__ping_tou_m5_12_6"
                            mass="0.0001" class="left_connect1_default" />

                        <body name="left_connect2_body" pos="-0.01042 0.01425 0.05909">
                            <joint name="left_connect2_joint" type="hinge" axis="0 1 0" />
                            <site name="left_connect2" size="0.001" rgba="1 0 0 1"
                                pos="0 -0.0021 -0.199999" />
                            <geom type="mesh" mesh="cj_003___left_connect2_1_m6_10_1_dian_pian__1"
                                mass="0.0001" class="left_connect2_default" />
                            <geom type="mesh" mesh="cj_003___left_connect2_1_m6_10_1_dian_pian__2"
                                mass="0.0001" class="left_connect2_default" />
                            <geom type="mesh" mesh="cj_003___left_connect2_1_m6_18_2_dian_pian__1"
                                mass="0.0001" class="left_connect2_default" />
                            <geom type="mesh" mesh="cj_003___left_connect2_1_m6_18_2_dian_pian__2"
                                mass="0.0001" class="left_connect2_default" />
                            <geom type="mesh"
                                mesh="cj_003___left_connect2_1__xiao_fa_lan_zhou_cheng__1"
                                mass="0.0041" class="left_connect2_default" />
                            <geom type="mesh"
                                mesh="cj_003___left_connect2_1__xiao_fa_lan_zhou_cheng__2"
                                mass="0.0041" class="left_connect2_default" />
                            <geom type="mesh" mesh="cj_003___left_connect2_1__lian_gan__1"
                                mass="0.0331" class="left_connect2_default" />
                        </body>
                    </body>
                </body>
            </body>


            <body name="right_hip_body" pos="-0.0301 -0.08 -0.159">
                <joint name="right_hip_joint" type="hinge" axis="1 0 0" />
                <geom type="mesh" mesh="cj_003___right_hip_1_6621_jiao_jie__1" mass="0.0016"
                    class="right_hip_default" />
                <geom type="mesh" mesh="cj_003___right_hip_1_6621_jiao_jie__2" mass="0.0016"
                    class="right_hip_default" />
                <geom type="mesh" mesh="cj_003___right_hip_1_6621_jiao_jie__3" mass="0.0016"
                    class="right_hip_default" />
                <geom type="mesh" mesh="cj_003___right_hip_1_6621_jiao_jie__4" mass="0.0016"
                    class="right_hip_default" />
                <geom type="mesh" mesh="cj_003___right_hip_1_6621_jiao_jie__5" mass="0.0016"
                    class="right_hip_default" />
                <geom type="mesh" mesh="cj_003___right_hip_1_6621_jiao_jie__6" mass="0.0016"
                    class="right_hip_default" />
                <geom type="mesh"
                    mesh="cj_003___right_hip_1_8009_rau_5005__wai_xing_chi_cun__20240809_1"
                    mass="0.9450" class="right_hip_default" />
                <geom type="mesh" mesh="cj_003___right_hip_1__da_tui_dian_ji_gu_ding_1_1"
                    mass="0.0286" class="right_hip_default" />
                <geom type="mesh" mesh="cj_003___right_hip_1__da_tui_dian_ji_gu_ding_2_1"
                    mass="0.0396" class="right_hip_default" />
                <geom type="mesh" mesh="cj_003___right_hip_1__da_tui_dian_ji_gu_ding_3_1"
                    mass="0.0363" class="right_hip_default" />
                <geom type="mesh" mesh="cj_003___right_hip_1__da_tui_dian_ji_gu_ding_4_1"
                    mass="0.0057" class="right_hip_default" />
                <geom type="mesh" mesh="cj_003___right_hip_1__da_tui_dian_ji_gu_ding_4_2"
                    mass="0.0057" class="right_hip_default" />
                <geom type="mesh" mesh="cj_003___right_hip_1__da_tui_dian_ji_gu_ding_5_1"
                    mass="0.0035" class="right_hip_default" />
                <geom type="mesh" mesh="cj_003___right_hip_1__ping_tou_m3_10_12" mass="0.0006"
                    class="right_hip_default" />
                <geom type="mesh" mesh="cj_003___right_hip_1__ping_tou_m3_10_13" mass="0.0006"
                    class="right_hip_default" />
                <geom type="mesh" mesh="cj_003___right_hip_1__ping_tou_m3_10_15" mass="0.0006"
                    class="right_hip_default" />
                <geom type="mesh" mesh="cj_003___right_hip_1__ping_tou_m3_10_16" mass="0.0006"
                    class="right_hip_default" />
                <geom type="mesh" mesh="cj_003___right_hip_1__ping_tou_m3_10_2" mass="0.0006"
                    class="right_hip_default" />
                <geom type="mesh" mesh="cj_003___right_hip_1__ping_tou_m3_10_3" mass="0.0006"
                    class="right_hip_default" />
                <geom type="mesh" mesh="cj_003___right_hip_1__ping_tou_m3_10_7" mass="0.0006"
                    class="right_hip_default" />
                <geom type="mesh" mesh="cj_003___right_hip_1__ping_tou_m3_10_8" mass="0.0006"
                    class="right_hip_default" />
                <geom type="mesh" mesh="cj_003___right_hip_1__ping_tou_m3_10_9" mass="0.0006"
                    class="right_hip_default" />
                <geom type="mesh" mesh="cj_003___right_hip_1__ping_tou_m3_16_1" mass="0.0008"
                    class="right_hip_default" />
                <geom type="mesh" mesh="cj_003___right_hip_1__ping_tou_m3_16_2" mass="0.0008"
                    class="right_hip_default" />
                <geom type="mesh" mesh="cj_003___right_hip_1__ping_tou_m3_16_3" mass="0.0008"
                    class="right_hip_default" />
                <geom type="mesh" mesh="cj_003___right_hip_1__ping_tou_m3_16_4" mass="0.0008"
                    class="right_hip_default" />
                <geom type="mesh" mesh="cj_003___right_hip_1__ping_tou_m4_10_1" mass="0.0009"
                    class="right_hip_default" />
                <geom type="mesh" mesh="cj_003___right_hip_1__ping_tou_m4_10_3" mass="0.0009"
                    class="right_hip_default" />
                <geom type="mesh" mesh="cj_003___right_hip_1__ping_tou_m4_10_4" mass="0.0009"
                    class="right_hip_default" />
                <geom type="mesh" mesh="cj_003___right_hip_1__ping_tou_m4_10_5" mass="0.0009"
                    class="right_hip_default" />
                <geom type="mesh" mesh="cj_003___right_hip_1__ping_tou_m4_10_6" mass="0.0009"
                    class="right_hip_default" />
                <geom type="mesh" mesh="cj_003___right_hip_1__ping_tou_m5_14_1" mass="0.0021"
                    class="right_hip_default" />
                <geom type="mesh" mesh="cj_003___right_hip_1__ping_tou_m5_14_2" mass="0.0021"
                    class="right_hip_default" />
                <geom type="mesh" mesh="cj_003___right_hip_1__ping_tou_m5_14_3" mass="0.0021"
                    class="right_hip_default" />
                <geom type="mesh" mesh="cj_003___right_hip_1__ping_tou_m5_14_4" mass="0.0021"
                    class="right_hip_default" />
                <geom type="mesh" mesh="cj_003___right_hip_1__ping_tou_m5_14_5" mass="0.0021"
                    class="right_hip_default" />
                <geom type="mesh" mesh="cj_003___right_hip_1__ping_tou_m5_14_6" mass="0.0021"
                    class="right_hip_default" />
                <geom type="mesh" mesh="cj_003___right_hip_1__bei_tou_m3_12_1" mass="0.0009"
                    class="right_hip_default" />
                <geom type="mesh" mesh="cj_003___right_hip_1__bei_tou_m3_12_2" mass="0.0009"
                    class="right_hip_default" />
                <geom type="mesh" mesh="cj_003___right_hip_1__bei_tou_m3_12_3" mass="0.0009"
                    class="right_hip_default" />
                <geom type="mesh" mesh="cj_003___right_hip_1__bei_tou_m3_12_4" mass="0.0009"
                    class="right_hip_default" />
                <geom type="mesh" mesh="cj_003___right_hip_1__bei_tou_m3_12_5" mass="0.0009"
                    class="right_hip_default" />
                <geom type="mesh" mesh="cj_003___right_hip_1__bei_tou_m3_12_6" mass="0.0009"
                    class="right_hip_default" />
                <geom type="mesh" mesh="cj_003___right_hip_1__bei_tou_m3_12_7" mass="0.0009"
                    class="right_hip_default" />
                <geom type="mesh" mesh="cj_003___right_hip_1__bei_tou_m3_12_8" mass="0.0009"
                    class="right_hip_default" />
                <geom type="mesh" mesh="cj_003___right_hip_1__bei_tou_m4_8_1" mass="0.0015"
                    class="right_hip_default" />
                <geom type="mesh" mesh="cj_003___right_hip_1__bei_tou_m4_8_2" mass="0.0015"
                    class="right_hip_default" />
                <geom type="mesh" mesh="cj_003___right_hip_1__bei_tou_m4_8_3" mass="0.0015"
                    class="right_hip_default" />
                <geom type="mesh" mesh="cj_003___right_hip_1__bei_tou_m4_8_4" mass="0.0015"
                    class="right_hip_default" />
                <geom type="mesh" mesh="cj_003___right_hip_1__bei_tou_m4_8_5" mass="0.0015"
                    class="right_hip_default" />
                <geom type="mesh" mesh="cj_003___right_hip_1__bei_tou_m4_8_6" mass="0.0015"
                    class="right_hip_default" />

                <body name="right_thigh_body" pos="-0.059 -0.0306 0">
                    <joint name="right_thigh_joint" type="hinge" axis="0 1 0" />
                    <geom type="mesh"
                        mesh="cj_003___right_thigh_1_8009_rau_5005__wai_xing_chi_cun__20240809_1"
                        mass="0.9450" class="right_thigh_default" />
                    <geom type="mesh"
                        mesh="cj_003___right_thigh_1_m5_40_shuang_tong_liu_jiao_luo_zhu__1"
                        mass="0.0099" class="right_thigh_default" />
                    <geom type="mesh"
                        mesh="cj_003___right_thigh_1_m5_40_shuang_tong_liu_jiao_luo_zhu__2"
                        mass="0.0099" class="right_thigh_default" />
                    <geom type="mesh"
                        mesh="cj_003___right_thigh_1_m5_40_shuang_tong_liu_jiao_luo_zhu__3"
                        mass="0.0099" class="right_thigh_default" />
                    <geom type="mesh" mesh="cj_003___right_thigh_1_m5_8_0_8_dian_pian__1"
                        mass="0.0001" class="right_thigh_default" />
                    <geom type="mesh" mesh="cj_003___right_thigh_1_m5_8_0_8_dian_pian__2"
                        mass="0.0001" class="right_thigh_default" />
                    <geom type="mesh" mesh="cj_003___right_thigh_1_m5_8_0_8_dian_pian__3"
                        mass="0.0001" class="right_thigh_default" />
                    <geom type="mesh" mesh="cj_003___right_thigh_1__wai_liu_jiao_m4_22_1"
                        mass="0.0024" class="right_thigh_default" />
                    <geom type="mesh" mesh="cj_003___right_thigh_1__wai_liu_jiao_m4_22_2"
                        mass="0.0024" class="right_thigh_default" />
                    <geom type="mesh" mesh="cj_003___right_thigh_1__wai_liu_jiao_m4_22_3"
                        mass="0.0024" class="right_thigh_default" />
                    <geom type="mesh" mesh="cj_003___right_thigh_1__wai_liu_jiao_m4_22_4"
                        mass="0.0024" class="right_thigh_default" />
                    <geom type="mesh" mesh="cj_003___right_thigh_1__wai_liu_jiao_m4_22_5"
                        mass="0.0024" class="right_thigh_default" />
                    <geom type="mesh" mesh="cj_003___right_thigh_1__da_tui_dian_ji_gu_ding_5_1"
                        mass="0.0035" class="right_thigh_default" />
                    <geom type="mesh"
                        mesh="cj_003___right_thigh_1__da_tui_dian_ji_gu_ding_dian_kuai__1"
                        mass="0.0205" class="right_thigh_default" />
                    <geom type="mesh"
                        mesh="cj_003___right_thigh_1__da_tui_dian_ji_gu_ding_dian_kuai__2"
                        mass="0.0205" class="right_thigh_default" />
                    <geom type="mesh" mesh="cj_003___right_thigh_1__da_tui_di_yi_ceng__1"
                        mass="0.1100" class="right_thigh_default" />
                    <geom type="mesh" mesh="cj_003___right_thigh_1__da_tui_di_er_ceng__1"
                        mass="0.1067" class="right_thigh_default" />
                    <geom type="mesh" mesh="cj_003___right_thigh_1__da_tui_xi_guan_jie_dian_kuai__1"
                        mass="0.0053" class="right_thigh_default" />
                    <geom type="mesh" mesh="cj_003___right_thigh_1__da_tui_xi_guan_jie_dian_kuai__2"
                        mass="0.0053" class="right_thigh_default" />
                    <geom type="mesh"
                        mesh="cj_003___right_thigh_1__xiao_tui_dian_ji_lian_jie___lv_he_jin__1"
                        mass="0.0720" class="right_thigh_default" />
                    <geom type="mesh" mesh="cj_003___right_thigh_1__ping_tou_m5_22_1" mass="0.0031"
                        class="right_thigh_default" />
                    <geom type="mesh" mesh="cj_003___right_thigh_1__ping_tou_m5_22_2" mass="0.0031"
                        class="right_thigh_default" />
                    <geom type="mesh" mesh="cj_003___right_thigh_1__ping_tou_m5_22_3" mass="0.0031"
                        class="right_thigh_default" />
                    <geom type="mesh" mesh="cj_003___right_thigh_1__ping_tou_m5_22_4" mass="0.0031"
                        class="right_thigh_default" />
                    <geom type="mesh" mesh="cj_003___right_thigh_1__ping_tou_m5_22_5" mass="0.0031"
                        class="right_thigh_default" />
                    <geom type="mesh" mesh="cj_003___right_thigh_1__ping_tou_m5_22_6" mass="0.0031"
                        class="right_thigh_default" />
                    <geom type="mesh" mesh="cj_003___right_thigh_1__bei_tou_m3_55_1" mass="0.0027"
                        class="right_thigh_default" />
                    <geom type="mesh" mesh="cj_003___right_thigh_1__bei_tou_m3_55_2" mass="0.0027"
                        class="right_thigh_default" />
                    <geom type="mesh" mesh="cj_003___right_thigh_1__bei_tou_m3_55_3" mass="0.0027"
                        class="right_thigh_default" />
                    <geom type="mesh" mesh="cj_003___right_thigh_1__bei_tou_m3_55_4" mass="0.0027"
                        class="right_thigh_default" />
                    <geom type="mesh" mesh="cj_003___right_thigh_1__bei_tou_m3_55_5" mass="0.0027"
                        class="right_thigh_default" />
                    <geom type="mesh" mesh="cj_003___right_thigh_1__bei_tou_m3_55_6" mass="0.0027"
                        class="right_thigh_default" />
                    <geom type="mesh" mesh="cj_003___right_thigh_1__bei_tou_m4_10_1" mass="0.0001"
                        class="right_thigh_default" />
                    <geom type="mesh" mesh="cj_003___right_thigh_1__bei_tou_m4_10_2" mass="0.0001"
                        class="right_thigh_default" />
                    <geom type="mesh" mesh="cj_003___right_thigh_1__bei_tou_m4_10_3" mass="0.0001"
                        class="right_thigh_default" />
                    <geom type="mesh" mesh="cj_003___right_thigh_1__bei_tou_m4_10_4" mass="0.0001"
                        class="right_thigh_default" />
                    <geom type="mesh" mesh="cj_003___right_thigh_1__bei_tou_m4_10_5" mass="0.0001"
                        class="right_thigh_default" />
                    <geom type="mesh" mesh="cj_003___right_thigh_1__bei_tou_m4_10_6" mass="0.0001"
                        class="right_thigh_default" />
                    <geom type="mesh" mesh="cj_003___right_thigh_1__bei_tou_m5_12_1" mass="0.0031"
                        class="right_thigh_default" />
                    <geom type="mesh" mesh="cj_003___right_thigh_1__bei_tou_m5_12_2" mass="0.0031"
                        class="right_thigh_default" />
                    <geom type="mesh" mesh="cj_003___right_thigh_1__bei_tou_m5_12_3" mass="0.0031"
                        class="right_thigh_default" />
                    <geom type="mesh" mesh="cj_003___right_thigh_1__bei_tou_m5_12_4" mass="0.0031"
                        class="right_thigh_default" />
                    <geom type="mesh" mesh="cj_003___right_thigh_1__bei_tou_m5_12_5" mass="0.0031"
                        class="right_thigh_default" />
                    <geom type="mesh" mesh="cj_003___right_thigh_1__bei_tou_m5_12_6" mass="0.0031"
                        class="right_thigh_default" />
                    <geom type="mesh" mesh="cj_003___right_thigh_1__xi_guan_jie_zhou_cheng__1"
                        mass="0.2920" class="right_thigh_default" />

                    <body name="right_calf_body" pos="0 -0.0489 -0.2">
                        <joint name="right_calf_joint" type="hinge" axis="0 1 0" />
                        <site name="right_connect1" size="0.001" rgba="0 1 0 1"
                            pos="-0.01042 -0.04475 0.05909" />
                        <geom type="mesh" mesh="cj_003___right_calf_1_m3_fang_hua_luo_mu__1"
                            mass="0.0001" class="right_calf_default" />
                        <geom type="mesh" mesh="cj_003___right_calf_1_m3_fang_hua_luo_mu__2"
                            mass="0.0001" class="right_calf_default" />
                        <geom type="mesh" mesh="cj_003___right_calf_1_m3_fang_hua_luo_mu__3"
                            mass="0.0001" class="right_calf_default" />
                        <geom type="mesh" mesh="cj_003___right_calf_1_m3_fang_hua_luo_mu__4"
                            mass="0.0001" class="right_calf_default" />
                        <geom type="mesh" mesh="cj_003___right_calf_1_m3_fang_hua_luo_mu__5"
                            mass="0.0001" class="right_calf_default" />
                        <geom type="mesh" mesh="cj_003___right_calf_1_m3_fang_hua_luo_mu__6"
                            mass="0.0001" class="right_calf_default" />
                        <geom type="mesh"
                            mesh="cj_003___right_calf_1_m4_12_shuang_tong_liu_jiao_luo_zhu__1"
                            mass="0.0019" class="right_calf_default" />
                        <geom type="mesh"
                            mesh="cj_003___right_calf_1_m4_12_shuang_tong_liu_jiao_luo_zhu__2"
                            mass="0.0019" class="right_calf_default" />
                        <geom type="mesh" mesh="cj_003___right_calf_1_m4_fang_hua_luo_mu__1"
                            mass="0.0001" class="right_calf_default" />
                        <geom type="mesh" mesh="cj_003___right_calf_1_m4_fang_hua_luo_mu__2"
                            mass="0.0001" class="right_calf_default" />
                        <geom type="mesh" mesh="cj_003___right_calf_1_m4_fang_hua_luo_mu__3"
                            mass="0.0001" class="right_calf_default" />
                        <geom type="mesh" mesh="cj_003___right_calf_1_m4_fang_hua_luo_mu__4"
                            mass="0.0001" class="right_calf_default" />
                        <geom type="mesh" mesh="cj_003___right_calf_1_m4_fang_hua_luo_mu__5"
                            mass="0.0001" class="right_calf_default" />
                        <geom type="mesh" mesh="cj_003___right_calf_1_m4_fang_hua_luo_mu__6"
                            mass="0.0001" class="right_calf_default" />
                        <geom type="mesh" mesh="cj_003___right_calf_1_m4_fang_hua_luo_mu__7"
                            mass="0.0001" class="right_calf_default" />
                        <geom type="mesh" mesh="cj_003___right_calf_1_m4_fang_hua_luo_mu__8"
                            mass="0.0001" class="right_calf_default" />
                        <geom type="mesh" mesh="cj_003___right_calf_1_m5_fang_hua_luo_mu__1"
                            mass="0.0001" class="right_calf_default" />
                        <geom type="mesh" mesh="cj_003___right_calf_1__sai_da_luo_si_m6_50_5_1"
                            mass="0.0144" class="right_calf_default" />
                        <geom type="mesh" mesh="cj_003___right_calf_1__xiao_tui__1" mass="0.0720"
                            class="right_calf_default" />
                        <geom type="mesh" mesh="cj_003___right_calf_1__xiao_tui__2" mass="0.0720"
                            class="right_calf_default" />
                        <geom type="mesh" mesh="cj_003___right_calf_1__ping_tou_m4_30_1"
                            mass="0.0025" class="right_calf_default" />
                        <geom type="mesh" mesh="cj_003___right_calf_1__ping_tou_m4_30_2"
                            mass="0.0025" class="right_calf_default" />
                        <geom type="mesh" mesh="cj_003___right_calf_1__ping_tou_m4_30_3"
                            mass="0.0025" class="right_calf_default" />
                        <geom type="mesh" mesh="cj_003___right_calf_1__ping_tou_m4_30_4"
                            mass="0.0025" class="right_calf_default" />
                        <geom type="mesh" mesh="cj_003___right_calf_1__ping_tou_m4_30_5"
                            mass="0.0025" class="right_calf_default" />
                        <geom type="mesh" mesh="cj_003___right_calf_1__ping_tou_m4_30_6"
                            mass="0.0025" class="right_calf_default" />
                        <geom type="mesh" mesh="cj_003___right_calf_1__ping_tou_m4_30_7"
                            mass="0.0025" class="right_calf_default" />
                        <geom type="mesh" mesh="cj_003___right_calf_1__ping_tou_m4_30_8"
                            mass="0.0025" class="right_calf_default" />
                        <geom type="mesh" mesh="cj_003___right_calf_1__bei_tou_m3_10_1"
                            mass="0.0008" class="right_calf_default" />
                        <geom type="mesh" mesh="cj_003___right_calf_1__bei_tou_m3_10_2"
                            mass="0.0008" class="right_calf_default" />
                        <geom type="mesh" mesh="cj_003___right_calf_1__bei_tou_m3_10_3"
                            mass="0.0008" class="right_calf_default" />
                        <geom type="mesh" mesh="cj_003___right_calf_1__bei_tou_m3_10_4"
                            mass="0.0008" class="right_calf_default" />
                        <geom type="mesh" mesh="cj_003___right_calf_1__bei_tou_m3_25_1"
                            mass="0.0015" class="right_calf_default" />
                        <geom type="mesh" mesh="cj_003___right_calf_1__bei_tou_m3_25_2"
                            mass="0.0015" class="right_calf_default" />
                        <geom type="mesh" mesh="cj_003___right_calf_1__bei_tou_m3_25_3"
                            mass="0.0015" class="right_calf_default" />
                        <geom type="mesh" mesh="cj_003___right_calf_1__bei_tou_m3_25_4"
                            mass="0.0015" class="right_calf_default" />
                        <geom type="mesh" mesh="cj_003___right_calf_1__bei_tou_m3_25_5"
                            mass="0.0015" class="right_calf_default" />
                        <geom type="mesh" mesh="cj_003___right_calf_1__bei_tou_m3_25_6"
                            mass="0.0015" class="right_calf_default" />
                        <geom type="mesh"
                            mesh="cj_003___right_calf_1__xi_guan_jie_xiao_tui_zhi_cheng_zhu__1"
                            mass="0.0018" class="right_calf_default" />
                        <geom type="mesh"
                            mesh="cj_003___right_calf_1__xi_guan_jie_lian_gan_dian_zhu__1"
                            mass="0.0331" class="right_calf_default" />

                        <geom type="mesh"
                            mesh="cj_003___right_wheel_foot_1__xiao_mi_shen_gou_qiu_gu_ding__1"
                            mass="0.0106" class="right_calf_default" pos="0.03994 -0.013 -0.22651" />
                        <geom type="mesh" mesh="cj_003___right_wheel_foot_1__ping_tou_m3_25_1"
                            mass="0.0015" class="right_calf_default" pos="0.03994 -0.013 -0.22651" />
                        <geom type="mesh" mesh="cj_003___right_wheel_foot_1__ping_tou_m3_25_2"
                            mass="0.0015" class="right_calf_default" pos="0.03994 -0.013 -0.22651" />
                        <geom type="mesh" mesh="cj_003___right_wheel_foot_1__ping_tou_m3_25_3"
                            mass="0.0015" class="right_calf_default" pos="0.03994 -0.013 -0.22651" />
                        <geom type="mesh" mesh="cj_003___right_wheel_foot_1__ping_tou_m3_25_4"
                            mass="0.0015" class="right_calf_default" pos="0.03994 -0.013 -0.22651" />
                        <geom type="mesh" mesh="cj_003___right_wheel_foot_1__ping_tou_m3_25_5"
                            mass="0.0015" class="right_calf_default" pos="0.03994 -0.013 -0.22651" />
                        <geom type="mesh" mesh="cj_003___right_wheel_foot_1__ping_tou_m3_25_6"
                            mass="0.0015" class="right_calf_default" pos="0.03994 -0.013 -0.22651" />
                        <geom type="mesh" mesh="cj_003___right_wheel_foot_1__ping_tou_m3_25_7"
                            mass="0.0015" class="right_calf_default" pos="0.03994 -0.013 -0.22651" />
                        <geom type="mesh" mesh="cj_003___right_wheel_foot_1__ping_tou_m3_25_8"
                            mass="0.0015" class="right_calf_default" pos="0.03994 -0.013 -0.22651" />
                        <geom type="mesh" mesh="cj_003___right_wheel_foot_1__ping_tou_m3_25_9"
                            mass="0.0015" class="right_calf_default" pos="0.03994 -0.013 -0.22651" />

                        <body name="right_point_foot2_body" pos="0 0 0">
                            <geom type="mesh" mesh="cj_003___right_point_foot2_1__lun_zu_mo_duan__1"
                                mass="0.0525" class="right_point_foot2_default" />
                            <geom type="mesh" mesh="cj_003___right_point_foot2_1__lun_zu_mo_duan__2"
                                mass="0.0525" class="right_point_foot2_default" />
                            <geom type="mesh"
                                mesh="cj_003___right_point_foot2_1__lun_zu_mo_duan___shen_gou_qiu_gu_ding__1"
                                mass="0.0525" class="right_point_foot2_default" />

                            <body name="right_wheel_foot_body" pos="0.03994 -0.013 -0.22651">
                                <joint name="right_wheel_joint" type="hinge" axis="0 1 0" />
                                <geom type="mesh" mesh="cj_003___right_wheel_foot_1_220_lun_gu__1"
                                    mass="0.3844" class="right_wheel_foot_default" />

                                <geom type="mesh"
                                    mesh="cj_003___right_wheel_foot_1__xiao_mi_dian_ji__1"
                                    mass="0.0001" class="right_wheel_foot_default" />
                                <geom type="mesh"
                                    mesh="cj_003___right_wheel_foot_1__xiao_mi_dian_ji_shen_gou_qiu_zhou_cheng__1"
                                    mass="0.0289" class="right_wheel_foot_default" />
                                <geom type="mesh"
                                    mesh="cj_003___right_wheel_foot_1__xiao_mi_dian_ji_shu_chu_dian_kuai___ya_ban__1"
                                    mass="0.0094" class="right_wheel_foot_default" />
                                <geom type="mesh"
                                    mesh="cj_003___right_wheel_foot_1__xiao_mi_dian_ji_shu_chu_dian_kuai___dian_pian__1"
                                    mass="0.0070" class="right_wheel_foot_default" />
                                <geom type="mesh"
                                    mesh="cj_003___right_wheel_foot_1__xiao_mi_dian_ji_shu_chu_dian_kuai___da_yin__1"
                                    mass="0.0053" class="right_wheel_foot_default" />

                                <geom type="mesh"
                                    mesh="cj_003___right_wheel_foot_1__bei_tou_m4_35_1"
                                    mass="0.0035" class="right_wheel_foot_default" />
                                <geom type="mesh"
                                    mesh="cj_003___right_wheel_foot_1__bei_tou_m4_35_2"
                                    mass="0.0035" class="right_wheel_foot_default" />
                                <geom type="mesh"
                                    mesh="cj_003___right_wheel_foot_1__bei_tou_m4_35_3"
                                    mass="0.0035" class="right_wheel_foot_default" />
                                <geom type="mesh"
                                    mesh="cj_003___right_wheel_foot_1__bei_tou_m4_35_4"
                                    mass="0.0035" class="right_wheel_foot_default" />
                                <geom type="mesh"
                                    mesh="cj_003___right_wheel_foot_1__bei_tou_m4_35_5"
                                    mass="0.0035" class="right_wheel_foot_default" />
                                <geom type="mesh"
                                    mesh="cj_003___right_wheel_foot_1__bei_tou_m4_35_6"
                                    mass="0.0035" class="right_wheel_foot_default" />
                                <geom type="mesh"
                                    mesh="cj_003___right_wheel_foot_1__xiang_jiao_bao_lun__1"
                                    mass="0.4817" class="right_wheel_foot_default" />
                                <geom type="mesh"
                                    mesh="cj_003___right_wheel_foot_1__lun_ping_mian_gun_zhen_zhou_cheng__1"
                                    mass="0.0384" class="right_wheel_foot_default" />
                            </body>

                        </body>
                    </body>
                </body>


                <!--  -->
                <body name="right_connect1_body" pos="-0.059 -0.1121 0">
                    <joint name="right_connect1_joint" type="hinge" axis="0 1 0" range="-2 0" />
                    <geom type="mesh" mesh="cj_003___right_connect1_1_8009_lian_gan__1"
                        mass="0.9450" class="right_connect1_default" />
                    <geom type="mesh" mesh="cj_003___right_connect1_1_m5_fang_hua_luo_mu__1"
                        mass="0.0001" class="right_connect1_default" />
                    <geom type="mesh" mesh="cj_003___right_connect1_1__sai_da_luo_si_m6_12_5_1"
                        mass="0.0063" class="right_connect1_default" />
                    <geom type="mesh" mesh="cj_003___right_connect1_1__ping_tou_m5_12_1"
                        mass="0.0001" class="right_connect1_default" />
                    <geom type="mesh" mesh="cj_003___right_connect1_1__ping_tou_m5_12_2"
                        mass="0.0001" class="right_connect1_default" />
                    <geom type="mesh" mesh="cj_003___right_connect1_1__ping_tou_m5_12_3"
                        mass="0.0001" class="right_connect1_default" />
                    <geom type="mesh" mesh="cj_003___right_connect1_1__ping_tou_m5_12_4"
                        mass="0.0001" class="right_connect1_default" />
                    <geom type="mesh" mesh="cj_003___right_connect1_1__ping_tou_m5_12_5"
                        mass="0.0001" class="right_connect1_default" />
                    <geom type="mesh" mesh="cj_003___right_connect1_1__ping_tou_m5_12_6"
                        mass="0.0001" class="right_connect1_default" />

                    <body name="right_connect2_body" pos="-0.01042 -0.01425 0.05909">
                        <joint name="right_connect2_joint" type="hinge" axis="0 1 0" />
                        <site name="right_connect2" size="0.001" rgba="1 0 0 1"
                            pos="0 0.0021 -0.199999" />
                        <geom type="mesh" mesh="cj_003___right_connect2_1_m6_10_1_dian_pian__1"
                            mass="0.0001" class="right_connect2_default" />
                        <geom type="mesh" mesh="cj_003___right_connect2_1_m6_10_1_dian_pian__2"
                            mass="0.0001" class="right_connect2_default" />
                        <geom type="mesh" mesh="cj_003___right_connect2_1_m6_18_2_dian_pian__1"
                            mass="0.0001" class="right_connect2_default" />
                        <geom type="mesh" mesh="cj_003___right_connect2_1_m6_18_2_dian_pian__2"
                            mass="0.0001" class="right_connect2_default" />
                        <geom type="mesh"
                            mesh="cj_003___right_connect2_1__xiao_fa_lan_zhou_cheng__1"
                            mass="0.0041" class="right_connect2_default" />
                        <geom type="mesh"
                            mesh="cj_003___right_connect2_1__xiao_fa_lan_zhou_cheng__2"
                            mass="0.0041" class="right_connect2_default" />
                        <geom type="mesh" mesh="cj_003___right_connect2_1__lian_gan__1"
                            mass="0.0331" class="right_connect2_default" />
                    </body>

                </body>

            </body>

        </body>
    </worldbody>

    <equality>
        <connect site1="left_connect1" site2="left_connect2" />
        <connect site1="right_connect1" site2="right_connect2" />
    </equality>

    <actuator>
        <position name="left_hip_joint" joint="left_hip_joint" kp="30.0" kv="0.8" ctrlrange="-0.5 0.5" forcerange="-20 20"/>
        <position name="left_thigh_joint" joint="left_thigh_joint" kp="30.0" kv="0.8" ctrlrange="0 1.0" forcerange="-20 20"/>
        <position name="left_calf_joint" joint="left_calf_joint" kp="30.0" kv="0.8" ctrlrange="-2.0 0" forcerange="-20 20"/>
        <position name="right_hip_joint" joint="right_hip_joint" kp="30.0" kv="0.8" ctrlrange="-0.5 0.5" forcerange="-20 20"/>
        <position name="right_thigh_joint" joint="right_thigh_joint" kp="30.0" kv="0.8" ctrlrange="0 1.0" forcerange="-20 20"/>
        <position name="right_calf_joint" joint="right_calf_joint" kp="30.0" kv="0.8" ctrlrange="-2.0 0" forcerange="-20 20"/>
        <velocity name="left_wheel_joint" joint="left_wheel_joint" kv="5" />
        <velocity name="right_wheel_joint" joint="right_wheel_joint" kv="5" />
    </actuator>
    <sensor>
        <jointpos name='left_hip_joint_p' joint='left_hip_joint' />
        <jointpos name='left_thigh_joint_p' joint='left_thigh_joint' />
        <jointpos name='left_calf_joint_p' joint='left_calf_joint' />
        <jointpos name='right_hip_joint_p' joint='right_hip_joint' />
        <jointpos name='right_thigh_joint_p' joint='right_thigh_joint' />
        <jointpos name='right_calf_joint_p' joint='right_calf_joint' />
        <!-- <jointpos name='left_wheel_joint_p' joint='left_wheel_joint' />
        <jointpos name='right_wheel_joint_p' joint='right_wheel_joint' /> -->
    
        <jointvel name='left_hip_joint_v' joint='left_hip_joint' />
        <jointvel name='left_thigh_joint_v' joint='left_thigh_joint' />
        <jointvel name='left_calf_joint_v' joint='left_calf_joint' />
        <jointvel name='right_hip_joint_v' joint='right_hip_joint' />
        <jointvel name='right_thigh_joint_v' joint='right_thigh_joint' />
        <jointvel name='right_calf_joint_v' joint='right_calf_joint' />
        <jointvel name='left_wheel_joint_v' joint='left_wheel_joint' />
        <jointvel name='right_wheel_joint_v' joint='right_wheel_joint' />
    
        <framequat name='orientation' objtype='site' objname='imu' />
        <gyro name='base_ang_vel' site='imu' />
        <!-- <accelerometer name="projected_gravity" site="imu" /> -->
      </sensor>
</mujoco>
